<?xml version="1.0" ?>
<!-- =================================================================================== -->
<!-- |    This document was autogenerated by xacro from AzureLoong_sr.urdf.xacro       | -->
<!-- |    EDITING THIS FILE BY HAND IS NOT RECOMMENDED                                 | -->
<!-- =================================================================================== -->
<!-- =================================================================================== -->
<!-- |    This document was autogenerated by xacro from AzureLoong.urdf                | -->
<!-- |    EDITING THIS FILE BY HAND IS NOT RECOMMENDED                                 | -->
<!-- =================================================================================== -->
<!-- This URDF was automatically created by SolidWorks to URDF Exporter! Originally created by Stephen Brawner (brawner@gmail.com) 
     Commit Version: 1.6.0-4-g7f85cfe  Build Version: 1.6.7995.38578
     For more information, please see http://wiki.ros.org/sw_urdf_exporter -->
<robot name="OpenLoog">
  <link name="world_link"/>
  <joint name="world_to_base" type="fixed">
    <origin rpy="0 0 0" xyz="0 0 0"/>
    <parent link="world_link"/>
    <child link="base"/>
  </joint>
  <link name="base"/>
  <joint name="base_to_link" type="fixed">
    <origin rpy="0 0 0" xyz="0 0 0"/>
    <parent link="base"/>
    <child link="base_link"/>
  </joint>
  <link name="base_link">
    <inertial>
      <origin rpy="0 0 0" xyz="-0.0056641 -0.0013367 0.23829"/>
      <mass value="22.447"/>
      <inertia ixx="0.3742" ixy="0.0009471" ixz="0.004646" iyy="0.27691" iyz="0.0040142" izz="0.22104"/>
    </inertial>
    <visual>
      <origin rpy="0 0 0" xyz="0 0 0"/>
      <geometry>
        <mesh filename="package://azureloong_description/meshes/base_link.STL"/>
      </geometry>
      <material name="">
        <color rgba="0.75294 0.75294 0.75294 1"/>
      </material>
    </visual>
    <collision>
      <origin rpy="0 0 0" xyz="0 0 0"/>
      <geometry>
        <mesh filename="package://azureloong_description/meshes/base_link.STL"/>
      </geometry>
    </collision>
  </link>
  <link name="Link_head_yaw">
    <inertial>
      <origin rpy="0 0 0" xyz="4.6974E-12 -0.0020814 0.044801"/>
      <mass value="0.84249"/>
      <inertia ixx="0.000629" ixy="1.2848E-14" ixz="-1.5461E-10" iyy="0.0007003" iyz="-6.5E-06" izz="0.0005541"/>
    </inertial>
    <visual>
      <origin rpy="0 0 0" xyz="0 0 0"/>
      <geometry>
        <mesh filename="package://azureloong_description/meshes/Link_head_yaw.STL"/>
      </geometry>
      <material name="">
        <color rgba="0.89804 0.91765 0.92941 1"/>
      </material>
    </visual>
    <collision>
      <origin rpy="0 0 0" xyz="0 0 0"/>
      <geometry>
        <mesh filename="package://azureloong_description/meshes/Link_head_yaw.STL"/>
      </geometry>
    </collision>
  </link>
  <joint name="J_head_yaw" type="revolute">
    <origin rpy="0 0 0" xyz="0.009 0 0.4064"/>
    <parent link="base_link"/>
    <child link="Link_head_yaw"/>
    <axis xyz="0 0 1"/>
    <limit effort="26" lower="-1.5708" upper="1.5708" velocity="109.8"/>
  </joint>
  <link name="Link_head_pitch">
    <inertial>
      <origin rpy="0 0 0" xyz="0.020569 0.033004 0.125"/>
      <mass value="1.3943"/>
      <inertia ixx="0.0060059" ixy="9.4E-06" ixz="-0.0007564" iyy="0.00629" iyz="1.03E-05" izz="0.0048569"/>
    </inertial>
    <visual>
      <origin rpy="0 0 0" xyz="0 0 0"/>
      <geometry>
        <mesh filename="package://azureloong_description/meshes/Link_head_pitch.STL"/>
      </geometry>
      <material name="">
        <color rgba="0.69804 0.69804 0.69804 1"/>
      </material>
    </visual>
    <collision>
      <origin rpy="0 0 0" xyz="0 0 0"/>
      <geometry>
        <mesh filename="package://azureloong_description/meshes/Link_head_pitch.STL"/>
      </geometry>
    </collision>
  </link>
  <joint name="J_head_pitch" type="revolute">
    <origin rpy="0 0 0" xyz="0 -0.0345999999999997 0.0484999999999999"/>
    <parent link="Link_head_yaw"/>
    <child link="Link_head_pitch"/>
    <axis xyz="0 -1 0"/>
    <limit effort="26" lower="-0.7854" upper="0.7854" velocity="109.8"/>
  </joint>
  <link name="Link_arm_r_01">
    <inertial>
      <origin rpy="0 0 0" xyz="0.0044946 -0.038294 -1.8744E-06"/>
      <mass value="0.75641"/>
      <inertia ixx="0.00058712" ixy="-2.9803E-07" ixz="-5.8378E-09" iyy="0.00080305" iyz="3.6648E-08" izz="0.00084299"/>
    </inertial>
    <visual>
      <origin rpy="0 0 0" xyz="0 0 0"/>
      <geometry>
        <mesh filename="package://azureloong_description/meshes/Link_arm_r_01.STL"/>
      </geometry>
      <material name="">
        <color rgba="0.69804 0.69804 0.69804 1"/>
      </material>
    </visual>
    <collision>
      <origin rpy="0 0 0" xyz="0 0 0"/>
      <geometry>
        <mesh filename="package://azureloong_description/meshes/Link_arm_r_01.STL"/>
      </geometry>
    </collision>
  </link>
  <joint name="J_arm_r_01" type="revolute">
    <origin rpy="0 0 0" xyz="0.004 -0.1616 0.3922"/>
    <parent link="base_link"/>
    <child link="Link_arm_r_01"/>
    <axis xyz="0 -1 0"/>
    <limit effort="80" lower="-2.96706" upper="2.96706" velocity="3.14"/>
  </joint>
  <link name="Link_arm_r_02">
    <inertial>
      <origin rpy="0 0 0" xyz="0.042 -0.0674307499121858 -6.93889390390723E-18"/>
      <mass value="0.984999996273518"/>
      <inertia ixx="0.0017309882399251" ixy="9.79515256436727E-20" ixz="3.63988309726277E-19" iyy="0.00115401958000568" iyz="-4.42134220053852E-19" izz="0.00226269324370836"/>
    </inertial>
    <visual>
      <origin rpy="0 0 0" xyz="0 0 0"/>
      <geometry>
        <mesh filename="package://azureloong_description/meshes/Link_arm_r_02.STL"/>
      </geometry>
      <material name="">
        <color rgba="0.698039215686274 0.698039215686274 0.698039215686274 1"/>
      </material>
    </visual>
    <collision>
      <origin rpy="0 0 0" xyz="0 0 0"/>
      <geometry>
        <mesh filename="package://azureloong_description/meshes/Link_arm_r_02.STL"/>
      </geometry>
    </collision>
  </link>
  <joint name="J_arm_r_02" type="revolute">
    <origin rpy="0 0 0" xyz="-0.042 -0.041 0"/>
    <parent link="Link_arm_r_01"/>
    <child link="Link_arm_r_02"/>
    <axis xyz="-1 0 0"/>
    <limit effort="80" lower="-1.83260" upper="1.83260" velocity="3.14"/>
  </joint>
  <link name="Link_arm_r_03">
    <inertial>
      <origin rpy="0 0 0" xyz="-0.00141357502419955 -0.164662742175383 0.0207578924800774"/>
      <mass value="0.958999855228924"/>
      <inertia ixx="0.00206438134078715" ixy="-1.82014067823509E-05" ixz="5.1283136963991E-06" iyy="0.00080535412926664" iyz="0.000255265992194607" izz="0.00205099914609259"/>
    </inertial>
    <visual>
      <origin rpy="0 0 0" xyz="0 0 0"/>
      <geometry>
        <mesh filename="package://azureloong_description/meshes/Link_arm_r_03.STL"/>
      </geometry>
      <material name="">
        <color rgba="0.698039215686274 0.698039215686274 0.698039215686274 1"/>
      </material>
    </visual>
    <collision>
      <origin rpy="0 0 0" xyz="0 0 0"/>
      <geometry>
        <mesh filename="package://azureloong_description/meshes/Link_arm_r_03.STL"/>
      </geometry>
    </collision>
  </link>
  <joint name="J_arm_r_03" type="revolute">
    <origin rpy="0 0 0" xyz="0.042 -0.1226 0"/>
    <parent link="Link_arm_r_02"/>
    <child link="Link_arm_r_03"/>
    <axis xyz="0 -1 0"/>
    <limit effort="48" lower="-2.96706" upper="2.96706" velocity="3.14"/>
  </joint>
  <link name="Link_arm_r_04">
    <inertial>
      <origin rpy="0 0 0" xyz="-0.038727 -0.060767 -0.021003"/>
      <mass value="0.6"/>
      <inertia ixx="0.00070398" ixy="2.023E-05" ixz="1.1263E-05" iyy="0.00068085" iyz="-0.00010585" izz="0.0010653"/>
    </inertial>
    <visual>
      <origin rpy="0 0 0" xyz="0 0 0"/>
      <geometry>
        <mesh filename="package://azureloong_description/meshes/Link_arm_r_04.STL"/>
      </geometry>
      <material name="">
        <color rgba="0.69804 0.69804 0.69804 1"/>
      </material>
    </visual>
    <collision>
      <origin rpy="0 0 0" xyz="0 0 0"/>
      <geometry>
        <mesh filename="package://azureloong_description/meshes/Link_arm_r_04.STL"/>
      </geometry>
    </collision>
  </link>
  <joint name="J_arm_r_04" type="revolute">
    <origin rpy="0 0 0" xyz="0.0353 -0.1774 0.024"/>
    <parent link="Link_arm_r_03"/>
    <child link="Link_arm_r_04"/>
    <axis xyz="-1 0 0"/>
    <limit effort="48" lower="0" upper="2.96706" velocity="3.14"/>
  </joint>
  <link name="Link_arm_r_05">
    <inertial>
      <origin rpy="0 0 0" xyz="3.2712E-05 -0.068658 -0.00011178"/>
      <mass value="0.68976"/>
      <inertia ixx="0.0025225" ixy="-4E-07" ixz="8E-07" iyy="0.0004487" iyz="3.1E-06" izz="0.0024111"/>
    </inertial>
    <visual>
      <origin rpy="0 0 0" xyz="0 0 0"/>
      <geometry>
        <mesh filename="package://azureloong_description/meshes/Link_arm_r_05.STL"/>
      </geometry>
      <material name="">
        <color rgba="0.69804 0.69804 0.69804 1"/>
      </material>
    </visual>
    <collision>
      <origin rpy="0 0 0" xyz="0 0 0"/>
      <geometry>
        <mesh filename="package://azureloong_description/meshes/Link_arm_r_05.STL"/>
      </geometry>
    </collision>
  </link>
  <joint name="J_arm_r_05" type="revolute">
    <origin rpy="0 1.57 0" xyz="-0.0353 -0.1035 -0.024"/>
    <parent link="Link_arm_r_04"/>
    <child link="Link_arm_r_05"/>
    <axis xyz="0 -1 0"/>
    <limit effort="12.4" lower="-2.96706" upper="2.96706" velocity="6.28"/>
  </joint>
  <link name="Link_arm_r_06">
    <inertial>
      <origin rpy="0 0 0" xyz="0.026078 -8.9588E-07 0.0016637"/>
      <mass value="0.28"/>
      <inertia ixx="0.0001456" ixy="-7.7026E-10" ixz="-2.1456E-07" iyy="0.00015693" iyz="-2.4102E-09" izz="0.00010498"/>
    </inertial>
    <visual>
      <origin rpy="0 0 0" xyz="0 0 0"/>
      <geometry>
        <mesh filename="package://azureloong_description/meshes/Link_arm_r_06.STL"/>
      </geometry>
      <material name="">
        <color rgba="0.69804 0.69804 0.69804 1"/>
      </material>
    </visual>
    <collision>
      <origin rpy="0 0 0" xyz="0 0 0"/>
      <geometry>
        <mesh filename="package://azureloong_description/meshes/Link_arm_r_06.STL"/>
      </geometry>
    </collision>
  </link>
  <joint name="J_arm_r_06" type="revolute">
    <origin rpy="0 0 0" xyz="-0.0265 -0.1965 0"/>
    <parent link="Link_arm_r_05"/>
    <child link="Link_arm_r_06"/>
    <axis xyz="0 0 -1"/>
    <limit effort="12.4" lower="-1.8326" upper="1.8326" velocity="6.28"/>
  </joint>
  <link name="Link_arm_r_07">
    <inertial>
      <origin rpy="0 0 0" xyz="-0.007859 -0.15817 -0.027736"/>
      <mass value="0.61354"/>
      <inertia ixx="0.0025969" ixy="4.65E-05" ixz="-0.0001089" iyy="0.0007306" iyz="-1.47E-05" izz="0.0030104"/>
    </inertial>
    <visual>
      <origin rpy="0 0 0" xyz="0 0 0"/>
      <geometry>
        <mesh filename="package://azureloong_description/meshes/Link_arm_r_07.STL"/>
      </geometry>
      <material name="">
        <color rgba="0.77647 0.75686 0.73725 1"/>
      </material>
    </visual>
    <collision>
      <origin rpy="0 0 0" xyz="0 0 0"/>
      <geometry>
        <mesh filename="package://azureloong_description/meshes/Link_arm_r_07.STL"/>
      </geometry>
    </collision>
  </link>
  <joint name="J_arm_r_07" type="revolute">
    <origin rpy="0 0 0" xyz="0.0265 0 0.0318"/>
    <parent link="Link_arm_r_06"/>
    <child link="Link_arm_r_07"/>
    <axis xyz="-1 0 0"/>
    <limit effort="12.4" lower="-1.04720" upper="1.04720" velocity="6.28"/>
  </joint>
  <link name="Link_arm_r_palm"/>
  <joint name="J_arm_r_palm" type="fixed">
    <origin rpy="0 0 0" xyz="0 -0.15 0.01"/>
    <parent link="Link_arm_r_07"/>
    <child link="Link_arm_r_palm"/>
  </joint>
  <link name="Link_arm_l_palm"/>
  <joint name="J_arm_l_palm" type="fixed">
    <origin rpy="0 0 0" xyz="0 -0.15 0"/>
    <parent link="Link_arm_l_07"/>
    <child link="Link_arm_l_palm"/>
  </joint>

  <link name="io_teleop_ee_link_left"/>
  <joint name="io_teleop_ee_joint_left" type="fixed">
    <origin rpy="3.14 -1.57 0" xyz="0 0 0"/>
    <parent link="Link_arm_l_palm"/>
    <child link="io_teleop_ee_link_left"/>
  </joint>
  <link name="io_teleop_ee_link_right"/>
  <joint name="io_teleop_ee_joint_right" type="fixed">
    <origin rpy="3.14 1.57 0" xyz="0 0 0"/>
    <parent link="Link_arm_r_palm"/>
    <child link="io_teleop_ee_link_right"/>
  </joint>
  <joint name="J_arm_r_08" type="fixed">
    <origin rpy="1.5708 3.1416 0" xyz="0.0 -0.07 -0.035"/>
    <parent link="Link_arm_r_07"/>
    <child link="rh_palm"/>
  </joint>
  <material name="Grey">
    <color rgba="0.2 0.2 0.2 1.0"/>
  </material>
  <material name="LightGrey">
    <color rgba="0.6 0.6 0.6 1.0"/>
  </material>
  
  
  <link name="rh_palm">
    <inertial>
      <origin rpy="0 0 0" xyz="0 0 0.035"/>
      <mass value="0.3"/>
      <inertia ixx="0.0003581" ixy="0.0" ixz="0.0" iyy="0.0005287" iyz="0.0" izz="0.000191"/>
    </inertial>
    <visual>
      <origin rpy="0 0 0" xyz="0 0 0"/>
      <geometry name="rh_palm_visual">
        <mesh filename="package://sr_description/meshes/components/palm/palm_E3M5.dae" scale="0.001 0.001 0.001"/>
      </geometry>
      <material name="Grey"/>
    </visual>
    <collision>
      <origin rpy="0 0 0" xyz="0.011 0.0085 0.038"/>
      <geometry name="rh_palm_collision_geom">
        <box size="0.062 0.007 0.098"/>
      </geometry>
    </collision>
    <collision>
      <origin rpy="0 0 0" xyz="-0.002 -0.0035 0.038"/>
      <geometry>
        <box size="0.036 0.017 0.098"/>
      </geometry>
    </collision>
    <!-- palm complement below first finger -->
    <collision>
      <origin rpy="0 0 0" xyz="0.029 -0.0035 0.082"/>
      <geometry>
        <box size="0.026 0.017 0.010"/>
      </geometry>
    </collision>
    <collision>
      <origin rpy="0.2 0 0.25" xyz="0.0265 -0.001 0.070"/>
      <geometry>
        <box size="0.026 0.014 0.018"/>
      </geometry>
    </collision>
    <!-- thumb pulp side -->
    <collision>
      <origin rpy="0 0 0" xyz="0.0315 -0.0085 0.001"/>
      <geometry>
        <box size="0.021 0.027 0.024"/>
      </geometry>
    </collision>
    <!-- thumb pulp central -->
    <collision>
      <origin rpy="0 0 -0.48" xyz="0.0125 -0.015 0.009"/>
      <geometry>
        <box size="0.022 0.005 0.040"/>
      </geometry>
    </collision>
    <!-- above middle finger-->
    <collision>
      <origin rpy="0 0 0" xyz="0.011 0 0.089"/>
      <geometry>
        <box size="0.018 0.024 0.004"/>
      </geometry>
    </collision>
    <!-- metacarpal side-->
    <collision>
      <origin rpy="0 0 0" xyz="-0.03 0 0.009"/>
      <geometry>
        <box size="0.020 0.024 0.040"/>
      </geometry>
    </collision>
  </link>
  <link name="rh_ffknuckle">
    <inertial>
      <origin rpy="0 0 0" xyz="0 0 0"/>
      <mass value="0.008"/>
      <inertia ixx="0.00000026" ixy="0.0" ixz="0.0" iyy="0.00000026" iyz="0.0" izz="0.00000032"/>
    </inertial>
    <visual>
      <origin rpy="0 0 0" xyz="0 0 0.0005"/>
      <geometry name="rh_ffknuckle_visual">
        <mesh filename="package://sr_description/meshes/components/f_knuckle/f_knuckle_E3M5.dae" scale="0.001 0.001 0.001"/>
      </geometry>
      <material name="LightGrey"/>
    </visual>
    <collision>
      <origin rpy="0 1.5708 0" xyz="0 0 0"/>
      <geometry name="rh_ffknuckle_collision_geom">
        <cylinder length="0.014" radius="0.007"/>
      </geometry>
    </collision>
  </link>
  <joint name="rh_FFJ4" type="revolute">
    <parent link="rh_palm"/>
    <child link="rh_ffknuckle"/>
    <!--<origin xyz="0.033 0 0.095" rpy="0 0 0" />-->
    <origin rpy="0 0 0" xyz="0.033 0 0.095"/>
    <axis xyz="0 -1 0"/>
    <limit effort="2" lower="-0.3490658503988659" upper="0.3490658503988659" velocity="2.0"/>
    <dynamics damping="0.01"/>
  </joint>
  <gazebo reference="rh_FFJ4">
    <provideFeedback>1</provideFeedback>
    <implicitSpringDamper>1</implicitSpringDamper>
  </gazebo>
  <transmission name="rh_ffknuckle_transmission">
    <type>transmission_interface/SimpleTransmission</type>
    <actuator name="rh_FFJ4">
      <mechanicalReduction>1</mechanicalReduction>
      <hardwareInterface>hardware_interface/EffortJointInterface</hardwareInterface>
    </actuator>
    <joint name="rh_FFJ4">
      <hardwareInterface>hardware_interface/EffortJointInterface</hardwareInterface>
    </joint>
  </transmission>
  <gazebo reference="rh_ffknuckle">
    <!-- knuckle is not highly exposed, so bumper is not useful -->
    <material>Gazebo/Grey</material>
  </gazebo>
  <link name="rh_ffproximal">
    <inertial>
      <mass value="0.030"/>
      <origin xyz="0 0 0.0225"/>
      <inertia ixx="0.0000098" ixy="0.0" ixz="0.0" iyy="0.00001" iyz="0.0" izz="0.0000018"/>
    </inertial>
    <visual>
      <origin rpy="0 0 0" xyz="0 0 0"/>
      <geometry name="rh_ffproximal_visual">
        <mesh filename="package://sr_description/meshes/components/f_proximal/f_proximal_E3M5.dae" scale="0.001 0.001 0.001"/>
      </geometry>
      <material name="Grey"/>
    </visual>
    <collision>
      <origin rpy="0 0 0" xyz="0 0 0.025"/>
      <geometry name="rh_ffproximal_collision_geom">
        <cylinder length="0.040" radius="0.007"/>
      </geometry>
    </collision>
  </link>
  <joint name="rh_FFJ3" type="revolute">
    <parent link="rh_ffknuckle"/>
    <child link="rh_ffproximal"/>
    <origin rpy="0 0 0" xyz="0 0 0"/>
    <axis xyz="1 0 0"/>
    <limit effort="2" lower="0" upper="1.5707963267948966" velocity="2.0"/>
    <dynamics damping="0.01"/>
  </joint>
  <gazebo reference="rh_FFJ3">
    <provideFeedback>1</provideFeedback>
    <implicitSpringDamper>1</implicitSpringDamper>
  </gazebo>
  <transmission name="rh_ffproximal_transmission">
    <type>transmission_interface/SimpleTransmission</type>
    <actuator name="rh_FFJ3">
      <mechanicalReduction>1</mechanicalReduction>
      <hardwareInterface>hardware_interface/EffortJointInterface</hardwareInterface>
    </actuator>
    <joint name="rh_FFJ3">
      <hardwareInterface>hardware_interface/EffortJointInterface</hardwareInterface>
    </joint>
  </transmission>
  <gazebo reference="rh_ffproximal">
    <selfCollide>true</selfCollide>
  </gazebo>
  <link name="rh_ffmiddle">
    <inertial>
      <origin rpy="0 0 0" xyz="0 0 0.0125"/>
      <mass value="0.017"/>
      <inertia ixx="0.0000026" ixy="0.0" ixz="0.0" iyy="0.0000027" iyz="0.0" izz="0.00000087"/>
    </inertial>
    <visual>
      <origin rpy="0 0 0" xyz="0 0 0"/>
      <geometry name="rh_ffmiddle_visual">
        <mesh filename="package://sr_description/meshes/components/f_middle/f_middle_E3M5.dae" scale="0.001 0.001 0.001"/>
      </geometry>
      <material name="Grey"/>
    </visual>
    <collision>
      <origin rpy="0 0 0" xyz="0 0 0.0125"/>
      <geometry name="rh_ffmiddle_collision_geom">
        <cylinder length="0.025" radius="0.007"/>
      </geometry>
    </collision>
    <collision>
      <origin rpy="0 0 0" xyz="0 0 0.0"/>
      <geometry>
        <sphere radius="0.007"/>
      </geometry>
    </collision>
    <collision>
      <origin rpy="0 0 0" xyz="0 0 0.025"/>
      <geometry>
        <sphere radius="0.007"/>
      </geometry>
    </collision>
  </link>
  <joint name="rh_FFJ2" type="revolute">
    <parent link="rh_ffproximal"/>
    <child link="rh_ffmiddle"/>
    <origin rpy="0 0 0" xyz="0 0 0.045"/>
    <axis xyz="1 0 0"/>
    <limit effort="2" lower="0" upper="1.5707963267948966" velocity="2.0"/>
    <dynamics damping="0.01"/>
  </joint>
  <gazebo reference="rh_FFJ2">
    <provideFeedback>1</provideFeedback>
    <implicitSpringDamper>1</implicitSpringDamper>
  </gazebo>
  <transmission name="rh_ffmiddle_transmission">
    <type>transmission_interface/SimpleTransmission</type>
    <actuator name="rh_FFJ1">
      <mechanicalReduction>1</mechanicalReduction>
      <hardwareInterface>hardware_interface/EffortJointInterface</hardwareInterface>
    </actuator>
    <joint name="rh_FFJ1">
      <hardwareInterface>hardware_interface/EffortJointInterface</hardwareInterface>
    </joint>
  </transmission>
  <transmission name="rh_ffj2_transmission">
    <type>transmission_interface/SimpleTransmission</type>
    <actuator name="rh_FFJ2">
      <mechanicalReduction>1</mechanicalReduction>
      <hardwareInterface>hardware_interface/EffortJointInterface</hardwareInterface>
    </actuator>
    <joint name="rh_FFJ2">
      <hardwareInterface>hardware_interface/EffortJointInterface</hardwareInterface>
    </joint>
  </transmission>
  <transmission name="rh_mfj2_transmission">
    <type>transmission_interface/SimpleTransmission</type>
    <actuator name="rh_MFJ2">
      <mechanicalReduction>1</mechanicalReduction>
      <hardwareInterface>hardware_interface/EffortJointInterface</hardwareInterface>
    </actuator>
    <joint name="rh_MFJ2">
      <hardwareInterface>hardware_interface/EffortJointInterface</hardwareInterface>
    </joint>
  </transmission>
  <transmission name="rh_rfj2_transmission">
    <type>transmission_interface/SimpleTransmission</type>
    <actuator name="rh_RFJ2">
      <mechanicalReduction>1</mechanicalReduction>
      <hardwareInterface>hardware_interface/EffortJointInterface</hardwareInterface>
    </actuator>
    <joint name="rh_RFJ2">
      <hardwareInterface>hardware_interface/EffortJointInterface</hardwareInterface>
    </joint>
  </transmission>
  <transmission name="rh_lfj2_transmission">
    <type>transmission_interface/SimpleTransmission</type>
    <actuator name="rh_LFJ2">
      <mechanicalReduction>1</mechanicalReduction>
      <hardwareInterface>hardware_interface/EffortJointInterface</hardwareInterface>
    </actuator>
    <joint name="rh_LFJ2">
      <hardwareInterface>hardware_interface/EffortJointInterface</hardwareInterface>
    </joint>
  </transmission>
  <gazebo reference="rh_ffmiddle">
    <selfCollide>true</selfCollide>
  </gazebo>
  <link name="rh_ffdistal">
    <inertial>
      <mass value="0.012"/>
      <origin xyz="0 0 0.012"/>
      <inertia ixx="0.00000094" ixy="0.0" ixz="0.0" iyy="0.0000011" iyz="0.0" izz="0.00000053"/>
    </inertial>
    <visual>
      <origin rpy="0 0 0" xyz="0 0 0"/>
      <geometry name="rh_ffdistal_visual">
        <mesh filename="package://sr_description/meshes/components/f_distal/pst/f_distal_pst.dae" scale="0.001 0.001 0.001"/>
      </geometry>
    </visual>
    <collision>
      <origin rpy="0 0 0" xyz="0 0 0"/>
      <geometry name="rh_ffdistal_collision_geom">
        <mesh filename="package://sr_description/meshes/components/f_distal/pst/f_distal_pst.dae" scale="0.001 0.001 0.001"/>
      </geometry>
    </collision>
  </link>
  <joint name="rh_FFJ1" type="revolute">
    <parent link="rh_ffmiddle"/>
    <child link="rh_ffdistal"/>
    <origin rpy="0 0 0" xyz="0 0 0.025"/>
    <axis xyz="1 0 0"/>
    <!-- standard distal joint -->
    <limit effort="2" lower="0" upper="1.5707963267948966" velocity="2.0"/>
    <dynamics damping="0.01"/>
  </joint>
  <gazebo reference="rh_FFJ1">
    <provideFeedback>1</provideFeedback>
    <implicitSpringDamper>1</implicitSpringDamper>
  </gazebo>
  <link name="rh_fftip">
    <inertial>
      <mass value="0.001"/>
      <inertia ixx="0.0" ixy="0.0" ixz="0.0" iyy="0.0" iyz="0.0" izz="0.0"/>
    </inertial>
  </link>
  <joint name="rh_FFtip" type="fixed">
    <parent link="rh_ffdistal"/>
    <child link="rh_fftip"/>
    <origin rpy="0 0 0" xyz="0 0 0.026"/>
  </joint>
  <gazebo reference="rh_ffdistal">
    <sensor name="rh_ffdistal_contact" type="contact">
      <always_on>1</always_on>
      <update_rate>1000.0</update_rate>
      <contact>
        <collision>rh_ffdistal_collision</collision>
        <topic>rh_ffdistal_collision</topic>
      </contact>
      <plugin filename="libgazebo_ros_bumper.so" name="rh_ffdistal_gazebo_ros_bumper_controller">
        <alwaysOn>true</alwaysOn>
        <frameName>rh_ffdistal</frameName>
        <updateRate>100.0</updateRate>
        <bumperTopicName>contacts/rh_ff/distal</bumperTopicName>
      </plugin>
    </sensor>
    <mu1 value="500.0"/>
    <mu2 value="500.0"/>
    <kp value="10000000.0"/>
    <kd value="100000.0"/>
    <selfCollide>true</selfCollide>
  </gazebo>
  <link name="rh_mfknuckle">
    <inertial>
      <origin rpy="0 0 0" xyz="0 0 0"/>
      <mass value="0.008"/>
      <inertia ixx="0.00000026" ixy="0.0" ixz="0.0" iyy="0.00000026" iyz="0.0" izz="0.00000032"/>
    </inertial>
    <visual>
      <origin rpy="0 0 0" xyz="0 0 0.0005"/>
      <geometry name="rh_mfknuckle_visual">
        <mesh filename="package://sr_description/meshes/components/f_knuckle/f_knuckle_E3M5.dae" scale="0.001 0.001 0.001"/>
      </geometry>
      <material name="LightGrey"/>
    </visual>
    <collision>
      <origin rpy="0 1.5708 0" xyz="0 0 0"/>
      <geometry name="rh_mfknuckle_collision_geom">
        <cylinder length="0.014" radius="0.007"/>
      </geometry>
    </collision>
  </link>
  <joint name="rh_MFJ4" type="revolute">
    <parent link="rh_palm"/>
    <child link="rh_mfknuckle"/>
    <!--<origin xyz="0.033 0 0.095" rpy="0 0 0" />-->
    <origin rpy="0 0 0" xyz="0.011 0 0.099"/>
    <axis xyz="0 -1 0"/>
    <limit effort="2" lower="-0.3490658503988659" upper="0.3490658503988659" velocity="2.0"/>
    <dynamics damping="0.01"/>
  </joint>
  <gazebo reference="rh_MFJ4">
    <provideFeedback>1</provideFeedback>
    <implicitSpringDamper>1</implicitSpringDamper>
  </gazebo>
  <transmission name="rh_mfknuckle_transmission">
    <type>transmission_interface/SimpleTransmission</type>
    <actuator name="rh_MFJ4">
      <mechanicalReduction>1</mechanicalReduction>
      <hardwareInterface>hardware_interface/EffortJointInterface</hardwareInterface>
    </actuator>
    <joint name="rh_MFJ4">
      <hardwareInterface>hardware_interface/EffortJointInterface</hardwareInterface>
    </joint>
  </transmission>
  <gazebo reference="rh_mfknuckle">
    <!-- knuckle is not highly exposed, so bumper is not useful -->
    <material>Gazebo/Grey</material>
  </gazebo>
  <link name="rh_mfproximal">
    <inertial>
      <mass value="0.030"/>
      <origin xyz="0 0 0.0225"/>
      <inertia ixx="0.0000098" ixy="0.0" ixz="0.0" iyy="0.00001" iyz="0.0" izz="0.0000018"/>
    </inertial>
    <visual>
      <origin rpy="0 0 0" xyz="0 0 0"/>
      <geometry name="rh_mfproximal_visual">
        <mesh filename="package://sr_description/meshes/components/f_proximal/f_proximal_E3M5.dae" scale="0.001 0.001 0.001"/>
      </geometry>
      <material name="Grey"/>
    </visual>
    <collision>
      <origin rpy="0 0 0" xyz="0 0 0.025"/>
      <geometry name="rh_mfproximal_collision_geom">
        <cylinder length="0.040" radius="0.007"/>
      </geometry>
    </collision>
  </link>
  <joint name="rh_MFJ3" type="revolute">
    <parent link="rh_mfknuckle"/>
    <child link="rh_mfproximal"/>
    <origin rpy="0 0 0" xyz="0 0 0"/>
    <axis xyz="1 0 0"/>
    <limit effort="2" lower="0" upper="1.5707963267948966" velocity="2.0"/>
    <dynamics damping="0.01"/>
  </joint>
  <gazebo reference="rh_MFJ3">
    <provideFeedback>1</provideFeedback>
    <implicitSpringDamper>1</implicitSpringDamper>
  </gazebo>
  <transmission name="rh_mfproximal_transmission">
    <type>transmission_interface/SimpleTransmission</type>
    <actuator name="rh_MFJ3">
      <mechanicalReduction>1</mechanicalReduction>
      <hardwareInterface>hardware_interface/EffortJointInterface</hardwareInterface>
    </actuator>
    <joint name="rh_MFJ3">
      <hardwareInterface>hardware_interface/EffortJointInterface</hardwareInterface>
    </joint>
  </transmission>
  <gazebo reference="rh_mfproximal">
    <selfCollide>true</selfCollide>
  </gazebo>
  <link name="rh_mfmiddle">
    <inertial>
      <origin rpy="0 0 0" xyz="0 0 0.0125"/>
      <mass value="0.017"/>
      <inertia ixx="0.0000026" ixy="0.0" ixz="0.0" iyy="0.0000027" iyz="0.0" izz="0.00000087"/>
    </inertial>
    <visual>
      <origin rpy="0 0 0" xyz="0 0 0"/>
      <geometry name="rh_mfmiddle_visual">
        <mesh filename="package://sr_description/meshes/components/f_middle/f_middle_E3M5.dae" scale="0.001 0.001 0.001"/>
      </geometry>
      <material name="Grey"/>
    </visual>
    <collision>
      <origin rpy="0 0 0" xyz="0 0 0.0125"/>
      <geometry name="rh_mfmiddle_collision_geom">
        <cylinder length="0.025" radius="0.007"/>
      </geometry>
    </collision>
    <collision>
      <origin rpy="0 0 0" xyz="0 0 0.0"/>
      <geometry>
        <sphere radius="0.007"/>
      </geometry>
    </collision>
    <collision>
      <origin rpy="0 0 0" xyz="0 0 0.025"/>
      <geometry>
        <sphere radius="0.007"/>
      </geometry>
    </collision>
  </link>
  <joint name="rh_MFJ2" type="revolute">
    <parent link="rh_mfproximal"/>
    <child link="rh_mfmiddle"/>
    <origin rpy="0 0 0" xyz="0 0 0.045"/>
    <axis xyz="1 0 0"/>
    <limit effort="2" lower="0" upper="1.5707963267948966" velocity="2.0"/>
    <dynamics damping="0.01"/>
  </joint>
  <gazebo reference="rh_MFJ2">
    <provideFeedback>1</provideFeedback>
    <implicitSpringDamper>1</implicitSpringDamper>
  </gazebo>
  <transmission name="rh_mfmiddle_transmission">
    <type>transmission_interface/SimpleTransmission</type>
    <actuator name="rh_MFJ1">
      <mechanicalReduction>1</mechanicalReduction>
      <hardwareInterface>hardware_interface/EffortJointInterface</hardwareInterface>
    </actuator>
    <joint name="rh_MFJ1">
      <hardwareInterface>hardware_interface/EffortJointInterface</hardwareInterface>
    </joint>
  </transmission>
  <gazebo reference="rh_mfmiddle">
    <selfCollide>true</selfCollide>
  </gazebo>
  <link name="rh_mfdistal">
    <inertial>
      <mass value="0.012"/>
      <origin xyz="0 0 0.012"/>
      <inertia ixx="0.00000094" ixy="0.0" ixz="0.0" iyy="0.0000011" iyz="0.0" izz="0.00000053"/>
    </inertial>
    <visual>
      <origin rpy="0 0 0" xyz="0 0 0"/>
      <geometry name="rh_mfdistal_visual">
        <mesh filename="package://sr_description/meshes/components/f_distal/pst/f_distal_pst.dae" scale="0.001 0.001 0.001"/>
      </geometry>
    </visual>
    <collision>
      <origin rpy="0 0 0" xyz="0 0 0"/>
      <geometry name="rh_mfdistal_collision_geom">
        <mesh filename="package://sr_description/meshes/components/f_distal/pst/f_distal_pst.dae" scale="0.001 0.001 0.001"/>
      </geometry>
    </collision>
  </link>
  <joint name="rh_MFJ1" type="revolute">
    <parent link="rh_mfmiddle"/>
    <child link="rh_mfdistal"/>
    <origin rpy="0 0 0" xyz="0 0 0.025"/>
    <axis xyz="1 0 0"/>
    <!-- standard distal joint -->
    <limit effort="2" lower="0" upper="1.5707963267948966" velocity="2.0"/>
    <dynamics damping="0.01"/>
  </joint>
  <gazebo reference="rh_MFJ1">
    <provideFeedback>1</provideFeedback>
    <implicitSpringDamper>1</implicitSpringDamper>
  </gazebo>
  <link name="rh_mftip">
    <inertial>
      <mass value="0.001"/>
      <inertia ixx="0.0" ixy="0.0" ixz="0.0" iyy="0.0" iyz="0.0" izz="0.0"/>
    </inertial>
  </link>
  <joint name="rh_MFtip" type="fixed">
    <parent link="rh_mfdistal"/>
    <child link="rh_mftip"/>
    <origin rpy="0 0 0" xyz="0 0 0.026"/>
  </joint>
  <gazebo reference="rh_mfdistal">
    <sensor name="rh_mfdistal_contact" type="contact">
      <always_on>1</always_on>
      <update_rate>1000.0</update_rate>
      <contact>
        <collision>rh_mfdistal_collision</collision>
        <topic>rh_mfdistal_collision</topic>
      </contact>
      <plugin filename="libgazebo_ros_bumper.so" name="rh_mfdistal_gazebo_ros_bumper_controller">
        <alwaysOn>true</alwaysOn>
        <frameName>rh_mfdistal</frameName>
        <updateRate>100.0</updateRate>
        <bumperTopicName>contacts/rh_mf/distal</bumperTopicName>
      </plugin>
    </sensor>
    <mu1 value="500.0"/>
    <mu2 value="500.0"/>
    <kp value="10000000.0"/>
    <kd value="100000.0"/>
    <selfCollide>true</selfCollide>
  </gazebo>
  <link name="rh_rfknuckle">
    <inertial>
      <origin rpy="0 0 0" xyz="0 0 0"/>
      <mass value="0.008"/>
      <inertia ixx="0.00000026" ixy="0.0" ixz="0.0" iyy="0.00000026" iyz="0.0" izz="0.00000032"/>
    </inertial>
    <visual>
      <origin rpy="0 0 0" xyz="0 0 0.0005"/>
      <geometry name="rh_rfknuckle_visual">
        <mesh filename="package://sr_description/meshes/components/f_knuckle/f_knuckle_E3M5.dae" scale="0.001 0.001 0.001"/>
      </geometry>
      <material name="LightGrey"/>
    </visual>
    <collision>
      <origin rpy="0 1.5708 0" xyz="0 0 0"/>
      <geometry name="rh_rfknuckle_collision_geom">
        <cylinder length="0.014" radius="0.007"/>
      </geometry>
    </collision>
  </link>
  <joint name="rh_RFJ4" type="revolute">
    <parent link="rh_palm"/>
    <child link="rh_rfknuckle"/>
    <!--<origin xyz="0.033 0 0.095" rpy="0 0 0" />-->
    <origin rpy="0 0 0" xyz="-0.011 0 0.095"/>
    <axis xyz="0 1 0"/>
    <limit effort="2" lower="-0.3490658503988659" upper="0.3490658503988659" velocity="2.0"/>
    <dynamics damping="0.01"/>
  </joint>
  <gazebo reference="rh_RFJ4">
    <provideFeedback>1</provideFeedback>
    <implicitSpringDamper>1</implicitSpringDamper>
  </gazebo>
  <transmission name="rh_rfknuckle_transmission">
    <type>transmission_interface/SimpleTransmission</type>
    <actuator name="rh_RFJ4">
      <mechanicalReduction>1</mechanicalReduction>
      <hardwareInterface>hardware_interface/EffortJointInterface</hardwareInterface>
    </actuator>
    <joint name="rh_RFJ4">
      <hardwareInterface>hardware_interface/EffortJointInterface</hardwareInterface>
    </joint>
  </transmission>
  <gazebo reference="rh_rfknuckle">
    <!-- knuckle is not highly exposed, so bumper is not useful -->
    <material>Gazebo/Grey</material>
  </gazebo>
  <link name="rh_rfproximal">
    <inertial>
      <mass value="0.030"/>
      <origin xyz="0 0 0.0225"/>
      <inertia ixx="0.0000098" ixy="0.0" ixz="0.0" iyy="0.00001" iyz="0.0" izz="0.0000018"/>
    </inertial>
    <visual>
      <origin rpy="0 0 0" xyz="0 0 0"/>
      <geometry name="rh_rfproximal_visual">
        <mesh filename="package://sr_description/meshes/components/f_proximal/f_proximal_E3M5.dae" scale="0.001 0.001 0.001"/>
      </geometry>
      <material name="Grey"/>
    </visual>
    <collision>
      <origin rpy="0 0 0" xyz="0 0 0.025"/>
      <geometry name="rh_rfproximal_collision_geom">
        <cylinder length="0.040" radius="0.007"/>
      </geometry>
    </collision>
  </link>
  <joint name="rh_RFJ3" type="revolute">
    <parent link="rh_rfknuckle"/>
    <child link="rh_rfproximal"/>
    <origin rpy="0 0 0" xyz="0 0 0"/>
    <axis xyz="1 0 0"/>
    <limit effort="2" lower="0" upper="1.5707963267948966" velocity="2.0"/>
    <dynamics damping="0.01"/>
  </joint>
  <gazebo reference="rh_RFJ3">
    <provideFeedback>1</provideFeedback>
    <implicitSpringDamper>1</implicitSpringDamper>
  </gazebo>
  <transmission name="rh_rfproximal_transmission">
    <type>transmission_interface/SimpleTransmission</type>
    <actuator name="rh_RFJ3">
      <mechanicalReduction>1</mechanicalReduction>
      <hardwareInterface>hardware_interface/EffortJointInterface</hardwareInterface>
    </actuator>
    <joint name="rh_RFJ3">
      <hardwareInterface>hardware_interface/EffortJointInterface</hardwareInterface>
    </joint>
  </transmission>
  <gazebo reference="rh_rfproximal">
    <selfCollide>true</selfCollide>
  </gazebo>
  <link name="rh_rfmiddle">
    <inertial>
      <origin rpy="0 0 0" xyz="0 0 0.0125"/>
      <mass value="0.017"/>
      <inertia ixx="0.0000026" ixy="0.0" ixz="0.0" iyy="0.0000027" iyz="0.0" izz="0.00000087"/>
    </inertial>
    <visual>
      <origin rpy="0 0 0" xyz="0 0 0"/>
      <geometry name="rh_rfmiddle_visual">
        <mesh filename="package://sr_description/meshes/components/f_middle/f_middle_E3M5.dae" scale="0.001 0.001 0.001"/>
      </geometry>
      <material name="Grey"/>
    </visual>
    <collision>
      <origin rpy="0 0 0" xyz="0 0 0.0125"/>
      <geometry name="rh_rfmiddle_collision_geom">
        <cylinder length="0.025" radius="0.007"/>
      </geometry>
    </collision>
    <collision>
      <origin rpy="0 0 0" xyz="0 0 0.0"/>
      <geometry>
        <sphere radius="0.007"/>
      </geometry>
    </collision>
    <collision>
      <origin rpy="0 0 0" xyz="0 0 0.025"/>
      <geometry>
        <sphere radius="0.007"/>
      </geometry>
    </collision>
  </link>
  <joint name="rh_RFJ2" type="revolute">
    <parent link="rh_rfproximal"/>
    <child link="rh_rfmiddle"/>
    <origin rpy="0 0 0" xyz="0 0 0.045"/>
    <axis xyz="1 0 0"/>
    <limit effort="2" lower="0" upper="1.5707963267948966" velocity="2.0"/>
    <dynamics damping="0.01"/>
  </joint>
  <gazebo reference="rh_RFJ2">
    <provideFeedback>1</provideFeedback>
    <implicitSpringDamper>1</implicitSpringDamper>
  </gazebo>
  <transmission name="rh_rfmiddle_transmission">
    <type>transmission_interface/SimpleTransmission</type>
    <actuator name="rh_RFJ1">
      <mechanicalReduction>1</mechanicalReduction>
      <hardwareInterface>hardware_interface/EffortJointInterface</hardwareInterface>
    </actuator>
    <joint name="rh_RFJ1">
      <hardwareInterface>hardware_interface/EffortJointInterface</hardwareInterface>
    </joint>
  </transmission>
  <gazebo reference="rh_rfmiddle">
    <selfCollide>true</selfCollide>
  </gazebo>
  <link name="rh_rfdistal">
    <inertial>
      <mass value="0.012"/>
      <origin xyz="0 0 0.012"/>
      <inertia ixx="0.00000094" ixy="0.0" ixz="0.0" iyy="0.0000011" iyz="0.0" izz="0.00000053"/>
    </inertial>
    <visual>
      <origin rpy="0 0 0" xyz="0 0 0"/>
      <geometry name="rh_rfdistal_visual">
        <mesh filename="package://sr_description/meshes/components/f_distal/pst/f_distal_pst.dae" scale="0.001 0.001 0.001"/>
      </geometry>
    </visual>
    <collision>
      <origin rpy="0 0 0" xyz="0 0 0"/>
      <geometry name="rh_rfdistal_collision_geom">
        <mesh filename="package://sr_description/meshes/components/f_distal/pst/f_distal_pst.dae" scale="0.001 0.001 0.001"/>
      </geometry>
    </collision>
  </link>
  <joint name="rh_RFJ1" type="revolute">
    <parent link="rh_rfmiddle"/>
    <child link="rh_rfdistal"/>
    <origin rpy="0 0 0" xyz="0 0 0.025"/>
    <axis xyz="1 0 0"/>
    <!-- standard distal joint -->
    <limit effort="2" lower="0" upper="1.5707963267948966" velocity="2.0"/>
    <dynamics damping="0.01"/>
  </joint>
  <gazebo reference="rh_RFJ1">
    <provideFeedback>1</provideFeedback>
    <implicitSpringDamper>1</implicitSpringDamper>
  </gazebo>
  <link name="rh_rftip">
    <inertial>
      <mass value="0.001"/>
      <inertia ixx="0.0" ixy="0.0" ixz="0.0" iyy="0.0" iyz="0.0" izz="0.0"/>
    </inertial>
  </link>
  <joint name="rh_RFtip" type="fixed">
    <parent link="rh_rfdistal"/>
    <child link="rh_rftip"/>
    <origin rpy="0 0 0" xyz="0 0 0.026"/>
  </joint>
  <gazebo reference="rh_rfdistal">
    <sensor name="rh_rfdistal_contact" type="contact">
      <always_on>1</always_on>
      <update_rate>1000.0</update_rate>
      <contact>
        <collision>rh_rfdistal_collision</collision>
        <topic>rh_rfdistal_collision</topic>
      </contact>
      <plugin filename="libgazebo_ros_bumper.so" name="rh_rfdistal_gazebo_ros_bumper_controller">
        <alwaysOn>true</alwaysOn>
        <frameName>rh_rfdistal</frameName>
        <updateRate>100.0</updateRate>
        <bumperTopicName>contacts/rh_rf/distal</bumperTopicName>
      </plugin>
    </sensor>
    <mu1 value="500.0"/>
    <mu2 value="500.0"/>
    <kp value="10000000.0"/>
    <kd value="100000.0"/>
    <selfCollide>true</selfCollide>
  </gazebo>
  <link name="rh_lfmetacarpal">
    <inertial>
      <origin rpy="0 0.9599 0" xyz="0.03174867647058824 0 0.02235294117647059"/>
      <mass value="0.030"/>
      <inertia ixx="0.0000145" ixy="0.0" ixz="0.0" iyy="0.00001638" iyz="0.0" izz="0.000004272"/>
    </inertial>
    <visual>
      <origin rpy="0 0.9599 0" xyz="0 0 0"/>
      <geometry name="rh_lfmetacarpal_visual">
        <mesh filename="package://sr_description/meshes/components/lf_metacarpal/lf_metacarpal_E3M5.dae" scale="0.001 0.001 0.001"/>
      </geometry>
      <material name="Grey"/>
    </visual>
    <collision>
      <origin rpy="0 0.9599 0" xyz="0.026986375 0 0.019"/>
      <geometry name="rh_lfmetacarpal_collision_geom">
        <box size="0.018 0.024 0.040"/>
      </geometry>
    </collision>
  </link>
  <joint name="rh_LFJ5" type="revolute">
    <parent link="rh_palm"/>
    <child link="rh_lfmetacarpal"/>
    <origin rpy="0 -0.9599 0" xyz="-0.033 0 0.02071"/>
    <axis xyz="1 0 0"/>
    <limit effort="2" lower="0" upper="0.7853981633974483" velocity="2.0"/>
    <dynamics damping="0.01"/>
  </joint>
  <gazebo reference="rh_LFJ5">
    <provideFeedback>1</provideFeedback>
    <implicitSpringDamper>1</implicitSpringDamper>
  </gazebo>
  <transmission name="rh_lfmetacarpal_transmission">
    <type>transmission_interface/SimpleTransmission</type>
    <actuator name="rh_LFJ5">
      <mechanicalReduction>1</mechanicalReduction>
      <hardwareInterface>hardware_interface/EffortJointInterface</hardwareInterface>
    </actuator>
    <joint name="rh_LFJ5">
      <hardwareInterface>hardware_interface/EffortJointInterface</hardwareInterface>
    </joint>
  </transmission>
  <gazebo reference="rh_lfmetacarpal">
    <selfCollide>true</selfCollide>
  </gazebo>
  <link name="rh_lfknuckle">
    <inertial>
      <origin rpy="0 0 0" xyz="0 0 0"/>
      <mass value="0.008"/>
      <inertia ixx="0.00000026" ixy="0.0" ixz="0.0" iyy="0.00000026" iyz="0.0" izz="0.00000032"/>
    </inertial>
    <visual>
      <origin rpy="0 0 0" xyz="0 0 0.0005"/>
      <geometry name="rh_lfknuckle_visual">
        <mesh filename="package://sr_description/meshes/components/f_knuckle/f_knuckle_E3M5.dae" scale="0.001 0.001 0.001"/>
      </geometry>
      <material name="LightGrey"/>
    </visual>
    <collision>
      <origin rpy="0 1.5708 0" xyz="0 0 0"/>
      <geometry name="rh_lfknuckle_collision_geom">
        <cylinder length="0.014" radius="0.007"/>
      </geometry>
    </collision>
  </link>
  <joint name="rh_LFJ4" type="revolute">
    <parent link="rh_lfmetacarpal"/>
    <child link="rh_lfknuckle"/>
    <!--<origin xyz="0.033 0 0.095" rpy="0 0 0" />-->
    <origin rpy="0 0.9599 0" xyz="0.05397275 0 0.03779463"/>
    <axis xyz="0 1 0"/>
    <limit effort="2" lower="-0.3490658503988659" upper="0.3490658503988659" velocity="2.0"/>
    <dynamics damping="0.01"/>
  </joint>
  <gazebo reference="rh_LFJ4">
    <provideFeedback>1</provideFeedback>
    <implicitSpringDamper>1</implicitSpringDamper>
  </gazebo>
  <transmission name="rh_lfknuckle_transmission">
    <type>transmission_interface/SimpleTransmission</type>
    <actuator name="rh_LFJ4">
      <mechanicalReduction>1</mechanicalReduction>
      <hardwareInterface>hardware_interface/EffortJointInterface</hardwareInterface>
    </actuator>
    <joint name="rh_LFJ4">
      <hardwareInterface>hardware_interface/EffortJointInterface</hardwareInterface>
    </joint>
  </transmission>
  <gazebo reference="rh_lfknuckle">
    <!-- knuckle is not highly exposed, so bumper is not useful -->
    <material>Gazebo/Grey</material>
  </gazebo>
  <link name="rh_lfproximal">
    <inertial>
      <mass value="0.030"/>
      <origin xyz="0 0 0.0225"/>
      <inertia ixx="0.0000098" ixy="0.0" ixz="0.0" iyy="0.00001" iyz="0.0" izz="0.0000018"/>
    </inertial>
    <visual>
      <origin rpy="0 0 0" xyz="0 0 0"/>
      <geometry name="rh_lfproximal_visual">
        <mesh filename="package://sr_description/meshes/components/f_proximal/f_proximal_E3M5.dae" scale="0.001 0.001 0.001"/>
      </geometry>
      <material name="Grey"/>
    </visual>
    <collision>
      <origin rpy="0 0 0" xyz="0 0 0.025"/>
      <geometry name="rh_lfproximal_collision_geom">
        <cylinder length="0.040" radius="0.007"/>
      </geometry>
    </collision>
  </link>
  <joint name="rh_LFJ3" type="revolute">
    <parent link="rh_lfknuckle"/>
    <child link="rh_lfproximal"/>
    <origin rpy="0 0 0" xyz="0 0 0"/>
    <axis xyz="1 0 0"/>
    <limit effort="2" lower="0" upper="1.5707963267948966" velocity="2.0"/>
    <dynamics damping="0.01"/>
  </joint>
  <gazebo reference="rh_LFJ3">
    <provideFeedback>1</provideFeedback>
    <implicitSpringDamper>1</implicitSpringDamper>
  </gazebo>
  <transmission name="rh_lfproximal_transmission">
    <type>transmission_interface/SimpleTransmission</type>
    <actuator name="rh_LFJ3">
      <mechanicalReduction>1</mechanicalReduction>
      <hardwareInterface>hardware_interface/EffortJointInterface</hardwareInterface>
    </actuator>
    <joint name="rh_LFJ3">
      <hardwareInterface>hardware_interface/EffortJointInterface</hardwareInterface>
    </joint>
  </transmission>
  <gazebo reference="rh_lfproximal">
    <selfCollide>true</selfCollide>
  </gazebo>
  <link name="rh_lfmiddle">
    <inertial>
      <origin rpy="0 0 0" xyz="0 0 0.0125"/>
      <mass value="0.017"/>
      <inertia ixx="0.0000026" ixy="0.0" ixz="0.0" iyy="0.0000027" iyz="0.0" izz="0.00000087"/>
    </inertial>
    <visual>
      <origin rpy="0 0 0" xyz="0 0 0"/>
      <geometry name="rh_lfmiddle_visual">
        <mesh filename="package://sr_description/meshes/components/f_middle/f_middle_E3M5.dae" scale="0.001 0.001 0.001"/>
      </geometry>
      <material name="Grey"/>
    </visual>
    <collision>
      <origin rpy="0 0 0" xyz="0 0 0.0125"/>
      <geometry name="rh_lfmiddle_collision_geom">
        <cylinder length="0.025" radius="0.007"/>
      </geometry>
    </collision>
    <collision>
      <origin rpy="0 0 0" xyz="0 0 0.0"/>
      <geometry>
        <sphere radius="0.007"/>
      </geometry>
    </collision>
    <collision>
      <origin rpy="0 0 0" xyz="0 0 0.025"/>
      <geometry>
        <sphere radius="0.007"/>
      </geometry>
    </collision>
  </link>
  <joint name="rh_LFJ2" type="revolute">
    <parent link="rh_lfproximal"/>
    <child link="rh_lfmiddle"/>
    <origin rpy="0 0 0" xyz="0 0 0.045"/>
    <axis xyz="1 0 0"/>
    <limit effort="2" lower="0" upper="1.5707963267948966" velocity="2.0"/>
    <dynamics damping="0.01"/>
  </joint>
  <gazebo reference="rh_LFJ2">
    <provideFeedback>1</provideFeedback>
    <implicitSpringDamper>1</implicitSpringDamper>
  </gazebo>
  <transmission name="rh_lfmiddle_transmission">
    <type>transmission_interface/SimpleTransmission</type>
    <actuator name="rh_LFJ1">
      <mechanicalReduction>1</mechanicalReduction>
      <hardwareInterface>hardware_interface/EffortJointInterface</hardwareInterface>
    </actuator>
    <joint name="rh_LFJ1">
      <hardwareInterface>hardware_interface/EffortJointInterface</hardwareInterface>
    </joint>
  </transmission>
  <gazebo reference="rh_lfmiddle">
    <selfCollide>true</selfCollide>
  </gazebo>
  <link name="rh_lfdistal">
    <inertial>
      <mass value="0.012"/>
      <origin xyz="0 0 0.012"/>
      <inertia ixx="0.00000094" ixy="0.0" ixz="0.0" iyy="0.0000011" iyz="0.0" izz="0.00000053"/>
    </inertial>
    <visual>
      <origin rpy="0 0 0" xyz="0 0 0"/>
      <geometry name="rh_lfdistal_visual">
        <mesh filename="package://sr_description/meshes/components/f_distal/pst/f_distal_pst.dae" scale="0.001 0.001 0.001"/>
      </geometry>
    </visual>
    <collision>
      <origin rpy="0 0 0" xyz="0 0 0"/>
      <geometry name="rh_lfdistal_collision_geom">
        <mesh filename="package://sr_description/meshes/components/f_distal/pst/f_distal_pst.dae" scale="0.001 0.001 0.001"/>
      </geometry>
    </collision>
  </link>
  <joint name="rh_LFJ1" type="revolute">
    <parent link="rh_lfmiddle"/>
    <child link="rh_lfdistal"/>
    <origin rpy="0 0 0" xyz="0 0 0.025"/>
    <axis xyz="1 0 0"/>
    <!-- standard distal joint -->
    <limit effort="2" lower="0" upper="1.5707963267948966" velocity="2.0"/>
    <dynamics damping="0.01"/>
  </joint>
  <gazebo reference="rh_LFJ1">
    <provideFeedback>1</provideFeedback>
    <implicitSpringDamper>1</implicitSpringDamper>
  </gazebo>
  <link name="rh_lftip">
    <inertial>
      <mass value="0.001"/>
      <inertia ixx="0.0" ixy="0.0" ixz="0.0" iyy="0.0" iyz="0.0" izz="0.0"/>
    </inertial>
  </link>
  <joint name="rh_LFtip" type="fixed">
    <parent link="rh_lfdistal"/>
    <child link="rh_lftip"/>
    <origin rpy="0 0 0" xyz="0 0 0.026"/>
  </joint>
  <gazebo reference="rh_lfdistal">
    <sensor name="rh_lfdistal_contact" type="contact">
      <always_on>1</always_on>
      <update_rate>1000.0</update_rate>
      <contact>
        <collision>rh_lfdistal_collision</collision>
        <topic>rh_lfdistal_collision</topic>
      </contact>
      <plugin filename="libgazebo_ros_bumper.so" name="rh_lfdistal_gazebo_ros_bumper_controller">
        <alwaysOn>true</alwaysOn>
        <frameName>rh_lfdistal</frameName>
        <updateRate>100.0</updateRate>
        <bumperTopicName>contacts/rh_lf/distal</bumperTopicName>
      </plugin>
    </sensor>
    <mu1 value="500.0"/>
    <mu2 value="500.0"/>
    <kp value="10000000.0"/>
    <kd value="100000.0"/>
    <selfCollide>true</selfCollide>
  </gazebo>
  <link name="rh_thbase">
    <inertial>
      <mass value="0.010"/>
      <origin rpy="0 0 0" xyz="0 0 0"/>
      <inertia ixx="0.00000016" ixy="0.0" ixz="0.0" iyy="0.00000016" iyz="0.0" izz="0.00000016"/>
    </inertial>
    <visual>
      <origin rpy="0 0 0" xyz="0 0 0"/>
      <geometry name="rh_thbase_visual">
        <box size="0.001 0.001 0.001"/>
      </geometry>
      <material name="shadow_thbase_material">
        <color rgba="0.5 0.5 0.5 1.0"/>
      </material>
    </visual>
    <collision>
      <origin rpy="0 0 0" xyz="0 0 0"/>
      <geometry name="rh_thbase_collision_geom">
        <sphere radius="0.011"/>
      </geometry>
    </collision>
  </link>
  <joint name="rh_THJ5" type="revolute">
    <parent link="rh_palm"/>
    <child link="rh_thbase"/>
    <origin rpy="-0.7853981633974483 0 -1.5707963267948966" xyz="0.034 -0.00858 0.029"/>
    <axis xyz="0 0 -1"/>
    <limit effort="5.0" lower="-1.0471975511965976" upper="1.0471975511965976" velocity="4.0"/>
    <dynamics damping="0.00"/>
  </joint>
  <gazebo reference="rh_THJ5">
    <provideFeedback>1</provideFeedback>
    <implicitSpringDamper>1</implicitSpringDamper>
  </gazebo>
  <transmission name="rh_thbase_transmission">
    <type>transmission_interface/SimpleTransmission</type>
    <actuator name="rh_THJ5">
      <mechanicalReduction>1</mechanicalReduction>
      <hardwareInterface>hardware_interface/EffortJointInterface</hardwareInterface>
    </actuator>
    <joint name="rh_THJ5">
      <hardwareInterface>hardware_interface/EffortJointInterface</hardwareInterface>
    </joint>
  </transmission>
  <gazebo reference="rh_thbase">
    <!-- base is inside the proximal and not exposed, so bumper is not needed -->
    <selfCollide>true</selfCollide>
  </gazebo>
  <link name="rh_thproximal">
    <inertial>
      <mass value="0.040"/>
      <origin rpy="0 0 0" xyz="0 0 0.019"/>
      <inertia ixx="0.0000136" ixy="0.0" ixz="0.0" iyy="0.0000136" iyz="0.0" izz="0.00000313"/>
    </inertial>
    <visual>
      <origin rpy="0 0 1.5707963267948966" xyz="0 0 0"/>
      <geometry name="rh_thproximal_visual">
        <mesh filename="package://sr_description/meshes/components/th_proximal/th_proximal_E3M5.dae" scale="0.001 0.001 0.001"/>
      </geometry>
      <material name="shadow_thproximal_material">
        <color rgba="0.2 0.2 0.2 1.0"/>
      </material>
    </visual>
    <collision>
      <origin rpy="0 0 0" xyz="0 0 0.020"/>
      <geometry name="rh_thproximal_collision_geom">
        <cylinder length="0.018" radius="0.012"/>
      </geometry>
    </collision>
  </link>
  <joint name="rh_THJ4" type="revolute">
    <parent link="rh_thbase"/>
    <child link="rh_thproximal"/>
    <origin rpy="0 0 0" xyz="0 0 0"/>
    <axis xyz="0 1 0"/>
    <limit effort="3" lower="0.0" upper="1.2217304763960306" velocity="4.0"/>
    <dynamics damping="0.00"/>
  </joint>
  <gazebo reference="rh_THJ4">
    <provideFeedback>1</provideFeedback>
    <implicitSpringDamper>1</implicitSpringDamper>
  </gazebo>
  <transmission name="rh_thproximal_transmission">
    <type>transmission_interface/SimpleTransmission</type>
    <actuator name="rh_THJ4">
      <mechanicalReduction>1</mechanicalReduction>
      <hardwareInterface>hardware_interface/EffortJointInterface</hardwareInterface>
    </actuator>
    <joint name="rh_THJ4">
      <hardwareInterface>hardware_interface/EffortJointInterface</hardwareInterface>
    </joint>
  </transmission>
  <gazebo reference="rh_thproximal">
    <selfCollide>true</selfCollide>
  </gazebo>
  <link name="rh_thhub">
    <inertial>
      <mass value="0.005"/>
      <origin rpy="0 0 0" xyz="0 0 0"/>
      <inertia ixx="0.000001" ixy="0.0" ixz="0.0" iyy="0.000001" iyz="0.0" izz="0.0000003"/>
    </inertial>
    <visual>
      <origin rpy="0 0 0" xyz="0 0 0"/>
      <geometry name="rh_thhub_visual">
        <box size="0.001 0.001 0.001"/>
      </geometry>
      <material name="shadow_thhub_material">
        <color rgba="0.7 0.7 0.7 1.0"/>
      </material>
    </visual>
    <collision>
      <origin rpy="0 0 0" xyz="0 0 0"/>
      <geometry name="rh_thhub_collision_geom">
        <sphere radius="0.010"/>
      </geometry>
    </collision>
  </link>
  <joint name="rh_THJ3" type="revolute">
    <parent link="rh_thproximal"/>
    <child link="rh_thhub"/>
    <origin rpy="0 0 0" xyz="0 0 0.038"/>
    <axis xyz="0 1 0"/>
    <limit effort="2.0" lower="0" upper="0.20943951023931953" velocity="4.0"/>
    <dynamics damping="0.00"/>
  </joint>
  <gazebo reference="rh_THJ3">
    <provideFeedback>1</provideFeedback>
    <implicitSpringDamper>1</implicitSpringDamper>
  </gazebo>
  <transmission name="rh_thhub_transmission">
    <type>transmission_interface/SimpleTransmission</type>
    <actuator name="rh_THJ3">
      <mechanicalReduction>1</mechanicalReduction>
      <hardwareInterface>hardware_interface/EffortJointInterface</hardwareInterface>
    </actuator>
    <joint name="rh_THJ3">
      <hardwareInterface>hardware_interface/EffortJointInterface</hardwareInterface>
    </joint>
  </transmission>
  <gazebo reference="rh_thhub">
    <!-- hub is inside the proximal and not exposed, so bumper is not needed -->
    <selfCollide>true</selfCollide>
  </gazebo>
  <link name="rh_thmiddle">
    <inertial>
      <mass value="0.020"/>
      <origin rpy="0 0 0" xyz="0 0 0.016"/>
      <inertia ixx="0.0000051" ixy="0.0" ixz="0.0" iyy="0.0000051" iyz="0.0" izz="0.00000121"/>
    </inertial>
    <visual>
      <origin rpy="0 0 1.5707963267948966" xyz="0 0 0"/>
      <geometry name="rh_thmiddle_visual">
        <mesh filename="package://sr_description/meshes/components/th_middle/th_middle_E3M5.dae" scale="0.001 0.001 0.001"/>
      </geometry>
      <material name="shadow_thmiddle_material">
        <color rgba="0.2 0.2 0.2 1.0"/>
      </material>
    </visual>
    <collision>
      <origin rpy="0 0 0" xyz="0 0 0.012"/>
      <geometry name="rh_thmiddle_collision_geom">
        <cylinder length="0.018" radius="0.011"/>
      </geometry>
    </collision>
    <collision>
      <origin rpy="0 0 0" xyz="0 0 0.019"/>
      <geometry>
        <sphere radius="0.011"/>
      </geometry>
    </collision>
    <collision>
      <origin rpy="0 1.5708 0" xyz="0 0 0.032"/>
      <geometry>
        <cylinder length="0.014" radius="0.010"/>
      </geometry>
    </collision>
  </link>
  <joint name="rh_THJ2" type="revolute">
    <parent link="rh_thhub"/>
    <child link="rh_thmiddle"/>
    <origin rpy="0 0 0" xyz="0 0 0"/>
    <axis xyz="1 0 0"/>
    <limit effort="2.0" lower="0" upper="0.6981317007977318" velocity="2.0"/>
    <dynamics damping="0.01"/>
  </joint>
  <gazebo reference="rh_THJ2">
    <provideFeedback>1</provideFeedback>
    <implicitSpringDamper>1</implicitSpringDamper>
  </gazebo>
  <transmission name="rh_thmiddle_transmission">
    <type>transmission_interface/SimpleTransmission</type>
    <actuator name="rh_THJ2">
      <mechanicalReduction>1</mechanicalReduction>
      <hardwareInterface>hardware_interface/EffortJointInterface</hardwareInterface>
    </actuator>
    <joint name="rh_THJ2">
      <hardwareInterface>hardware_interface/EffortJointInterface</hardwareInterface>
    </joint>
  </transmission>
  <gazebo reference="rh_thmiddle">
  </gazebo>
  <!-- common -->
  <link name="rh_thdistal">
    <inertial>
      <mass value="0.016"/>
      <origin rpy="0 0 0" xyz="0 0 0.01375"/>
      <inertia ixx="0.0000021" ixy="0.0" ixz="0.0" iyy="0.0000022" iyz="0.0" izz="0.000001"/>
    </inertial>
    <visual>
      <origin rpy="0 0 0" xyz="0 0 0"/>
      <geometry name="rh_thdistal_visual">
        <mesh filename="package://sr_description/meshes/components/th_distal/pst/th_distal_pst.dae" scale="0.001 0.001 0.001"/>
      </geometry>
      <material name="shadow_thmiddle_material">
        <color rgba="0.2 0.2 0.2 1.0"/>
      </material>
    </visual>
    <collision>
      <origin rpy="0 0 0" xyz="0 0 0"/>
      <geometry name="rh_thmiddle_collision_geom">
        <mesh filename="package://sr_description/meshes/components/th_distal/pst/th_distal_pst.dae" scale="0.001 0.001 0.001"/>
      </geometry>
    </collision>
  </link>
  <joint name="rh_THJ1" type="revolute">
    <parent link="rh_thmiddle"/>
    <child link="rh_thdistal"/>
    <origin rpy="0 0 0" xyz="0 0 0.032"/>
    <axis xyz="1 0 0"/>
    <limit effort="1.0" lower="0" upper="1.5707963267948966" velocity="4.0"/>
    <dynamics damping="0.00"/>
  </joint>
  <gazebo reference="rh_THJ1">
    <provideFeedback>1</provideFeedback>
    <implicitSpringDamper>1</implicitSpringDamper>
  </gazebo>
  <link name="rh_thtip">
    <inertial>
      <mass value="0.001"/>
      <inertia ixx="0.0" ixy="0.0" ixz="0.0" iyy="0.0" iyz="0.0" izz="0.0"/>
    </inertial>
  </link>
  <joint name="rh_thtip" type="fixed">
    <parent link="rh_thdistal"/>
    <child link="rh_thtip"/>
    <origin rpy="0 0 0" xyz="0 0 0.0275"/>
  </joint>
  <gazebo reference="rh_thdistal">
    <sensor name="rh_thdistal_contact" type="contact">
      <always_on>1</always_on>
      <update_rate>1000.0</update_rate>
      <contact>
        <collision>rh_thdistal_collision</collision>
        <topic>rh_thdistal_collision</topic>
      </contact>
      <plugin filename="libgazebo_ros_bumper.so" name="rh_thdistal_gazebo_ros_bumper_controller">
        <alwaysOn>true</alwaysOn>
        <frameName>rh_thdistal</frameName>
        <updateRate>100.0</updateRate>
        <bumperTopicName>contacts/rh_th/distal</bumperTopicName>
      </plugin>
    </sensor>
    <mu1 value="500.0"/>
    <mu2 value="500.0"/>
    <kp value="10000000.0"/>
    <kd value="100000.0"/>
    <selfCollide>true</selfCollide>
  </gazebo>
  <transmission name="rh_thdistal_transmission">
    <type>transmission_interface/SimpleTransmission</type>
    <actuator name="rh_THJ1">
      <mechanicalReduction>1</mechanicalReduction>
      <hardwareInterface>hardware_interface/EffortJointInterface</hardwareInterface>
    </actuator>
    <joint name="rh_THJ1">
      <hardwareInterface>hardware_interface/EffortJointInterface</hardwareInterface>
    </joint>
  </transmission>
  
  
  
  <link name="Link_arm_l_01">
    <inertial>
      <origin rpy="0 0 0" xyz="-0.00449464987882542 0.0382942125981936 -1.874402432607E-06"/>
      <mass value="0.756406339732892"/>
      <inertia ixx="0.000587115683146372" ixy="-2.98026052651538E-07" ixz="5.83781087215966E-09" iyy="0.000803052813361661" iyz="-3.66476835396106E-08" izz="0.000842985653484675"/>
    </inertial>
    <visual>
      <origin rpy="0 0 0" xyz="0 0 0"/>
      <geometry>
        <mesh filename="package://azureloong_description/meshes/Link_arm_l_01.STL"/>
      </geometry>
      <material name="">
        <color rgba="0.698039215686274 0.698039215686274 0.698039215686274 1"/>
      </material>
    </visual>
    <collision>
      <origin rpy="0 0 0" xyz="0 0 0"/>
      <geometry>
        <mesh filename="package://azureloong_description/meshes/Link_arm_l_01.STL"/>
      </geometry>
    </collision>
  </link>
  <joint name="J_arm_l_01" type="revolute">
    <origin rpy="0 0 0" xyz="0.004 0.1616 0.3922"/>
    <parent link="base_link"/>
    <child link="Link_arm_l_01"/>
    <axis xyz="0 1 0"/>
    <limit effort="80" lower="-2.96706" upper="2.96706" velocity="3.14"/>
  </joint>
  <link name="Link_arm_l_02">
    <inertial>
      <origin rpy="0 0 0" xyz="-0.042 0.0674307499121858 1.38777878078145E-17"/>
      <mass value="0.984999996273518"/>
      <inertia ixx="0.0017309882399251" ixy="1.48322871384691E-19" ixz="1.94588987195478E-19" iyy="0.00115401958000568" iyz="6.15989345249147E-19" izz="0.00226269324370836"/>
    </inertial>
    <visual>
      <origin rpy="0 0 0" xyz="0 0 0"/>
      <geometry>
        <mesh filename="package://azureloong_description/meshes/Link_arm_l_02.STL"/>
      </geometry>
      <material name="">
        <color rgba="0.698039215686274 0.698039215686274 0.698039215686274 1"/>
      </material>
    </visual>
    <collision>
      <origin rpy="0 0 0" xyz="0 0 0"/>
      <geometry>
        <mesh filename="package://azureloong_description/meshes/Link_arm_l_02.STL"/>
      </geometry>
    </collision>
  </link>
  <joint name="J_arm_l_02" type="revolute">
    <origin rpy="0 0 0" xyz="0.042 0.041 0"/>
    <parent link="Link_arm_l_01"/>
    <child link="Link_arm_l_02"/>
    <axis xyz="1 0 0"/>
    <limit effort="80" lower="-1.83260" upper="1.83260" velocity="3.14"/>
  </joint>
  <link name="Link_arm_l_03">
    <inertial>
      <origin rpy="0 0 0" xyz="0.00141357502419956 0.164662742175383 0.0207578924800774"/>
      <mass value="0.958999855228925"/>
      <inertia ixx="0.00206438134078715" ixy="-1.82014067823508E-05" ixz="-5.12831369639908E-06" iyy="0.000805354129266641" iyz="-0.000255265992194607" izz="0.00205099914609259"/>
    </inertial>
    <visual>
      <origin rpy="0 0 0" xyz="0 0 0"/>
      <geometry>
        <mesh filename="package://azureloong_description/meshes/Link_arm_l_03.STL"/>
      </geometry>
      <material name="">
        <color rgba="0.698039215686274 0.698039215686274 0.698039215686274 1"/>
      </material>
    </visual>
    <collision>
      <origin rpy="0 0 0" xyz="0 0 0"/>
      <geometry>
        <mesh filename="package://azureloong_description/meshes/Link_arm_l_03.STL"/>
      </geometry>
    </collision>
  </link>
  <joint name="J_arm_l_03" type="revolute">
    <origin rpy="0 0 0" xyz="-0.042 0.1226 0"/>
    <parent link="Link_arm_l_02"/>
    <child link="Link_arm_l_03"/>
    <axis xyz="0 1 0"/>
    <limit effort="48" lower="-2.96706" upper="2.96706" velocity="3.14"/>
  </joint>
  <link name="Link_arm_l_04">
    <inertial>
      <origin rpy="0 0 0" xyz="0.038726985904266 0.0607672244593032 -0.0210032450980798"/>
      <mass value="0.60000012303258"/>
      <inertia ixx="0.000703976141425558" ixy="2.02301178076816E-05" ixz="-1.12633779930363E-05" iyy="0.000680850033983237" iyz="0.000105852227353173" izz="0.00106526266740194"/>
    </inertial>
    <visual>
      <origin rpy="0 0 0" xyz="0 0 0"/>
      <geometry>
        <mesh filename="package://azureloong_description/meshes/Link_arm_l_04.STL"/>
      </geometry>
      <material name="">
        <color rgba="0.698039215686274 0.698039215686274 0.698039215686274 1"/>
      </material>
    </visual>
    <collision>
      <origin rpy="0 0 0" xyz="0 0 0"/>
      <geometry>
        <mesh filename="package://azureloong_description/meshes/Link_arm_l_04.STL"/>
      </geometry>
    </collision>
  </link>
  <joint name="J_arm_l_04" type="revolute">
    <origin rpy="0 0 0" xyz="-0.0353 0.1774 0.024"/>
    <parent link="Link_arm_l_03"/>
    <child link="Link_arm_l_04"/>
    <axis xyz="1 0 0"/>
    <limit effort="48" lower="0" upper="2.96706" velocity="3.14"/>
  </joint>
  <link name="Link_arm_l_05">
    <inertial>
      <origin rpy="0 0 0" xyz="-3.2712E-05 0.068658 -0.00011178"/>
      <mass value="0.68976"/>
      <inertia ixx="0.0025225" ixy="-4E-07" ixz="-8E-07" iyy="0.0004487" iyz="-3.1E-06" izz="0.0024111"/>
    </inertial>
    <visual>
      <origin rpy="0 0 0" xyz="0 0 0"/>
      <geometry>
        <mesh filename="package://azureloong_description/meshes/Link_arm_l_05.STL"/>
      </geometry>
      <material name="">
        <color rgba="0.69804 0.69804 0.69804 1"/>
      </material>
    </visual>
    <collision>
      <origin rpy="0 0 0" xyz="0 0 0"/>
      <geometry>
        <mesh filename="package://azureloong_description/meshes/Link_arm_l_05.STL"/>
      </geometry>
    </collision>
  </link>
  <joint name="J_arm_l_05" type="revolute">
    <origin rpy="0 1.57 0" xyz="0.0353 0.1035 -0.024"/>
    <parent link="Link_arm_l_04"/>
    <child link="Link_arm_l_05"/>
    <axis xyz="0 1 0"/>
    <limit effort="12.4" lower="-2.96706" upper="2.96706" velocity="6.28"/>
  </joint>
  <link name="Link_arm_l_06">
    <inertial>
      <origin rpy="0 0 0" xyz="-0.0260776548825596 8.95877202866657E-07 0.00166373234012217"/>
      <mass value="0.280000012776158"/>
      <inertia ixx="0.000145596926990102" ixy="-7.70263046256849E-10" ixz="2.14557176368931E-07" iyy="0.000156926535065694" iyz="2.41022657678511E-09" izz="0.000104981940665913"/>
    </inertial>
    <visual>
      <origin rpy="0 0 0" xyz="0 0 0"/>
      <geometry>
        <mesh filename="package://azureloong_description/meshes/Link_arm_l_06.STL"/>
      </geometry>
      <material name="">
        <color rgba="0.698039215686274 0.698039215686274 0.698039215686274 1"/>
      </material>
    </visual>
    <collision>
      <origin rpy="0 0 0" xyz="0 0 0"/>
      <geometry>
        <mesh filename="package://azureloong_description/meshes/Link_arm_l_06.STL"/>
      </geometry>
    </collision>
  </link>
  <joint name="J_arm_l_06" type="revolute">
    <origin rpy="0 0 0" xyz="0.0265 0.1965 0"/>
    <parent link="Link_arm_l_05"/>
    <child link="Link_arm_l_06"/>
    <axis xyz="0 0 1"/>
    <limit effort="12.4" lower="-1.8326" upper="1.8326" velocity="6.28"/>
  </joint>
  <link name="Link_arm_l_07">
    <inertial>
      <origin rpy="0 0 0" xyz="-0.0077872 0.15705 -0.027733"/>
      <mass value="0.61354"/>
      <inertia ixx="0.0025964" ixy="-4.66E-05" ixz="-0.0001089" iyy="0.0007306" iyz="1.47E-05" izz="0.00301"/>
    </inertial>
    <visual>
      <origin rpy="0 0 0" xyz="0 0 0"/>
      <geometry>
        <mesh filename="package://azureloong_description/meshes/Link_arm_l_07.STL"/>
      </geometry>
      <material name="">
        <color rgba="0.77647 0.75686 0.73725 1"/>
      </material>
    </visual>
    <collision>
      <origin rpy="0 0 0" xyz="0 0 0"/>
      <geometry>
        <mesh filename="package://azureloong_description/meshes/Link_arm_l_07.STL"/>
      </geometry>
    </collision>
  </link>
  <!--joint name="J_arm_l_07" type="revolute">
    <origin rpy="0 0 0" xyz="-0.0265 0 0.0318"/>
    <parent link="Link_arm_l_06"/>
    <child link="Link_arm_l_07"/>
    <axis xyz="0 0 1"/>
    <limit effort="12.4" lower="-1.04720" upper="1.04720" velocity="6.28"/>
  </joint-->
  <joint name="J_arm_l_07" type="revolute">
    <origin rpy="0 0 3.1416" xyz="-0.0265 0 0.0318"/>
    <parent link="Link_arm_l_06"/>
    <child link="Link_arm_l_07"/>
    <axis xyz="1 0 0"/>
    <limit effort="12.4" lower="-1.04720" upper="1.04720" velocity="6.28"/>
  </joint>
  
  
  
  
  
   <joint name="J_arm_l_08" type="fixed">
    <origin rpy="1.5708 3.1416 0" xyz="0.0 -0.07 -0.035"/>
    <parent link="Link_arm_l_07"/>
    <child link="lh_palm"/>
  </joint>  
    <link name="lh_palm">
    <inertial>
      <origin rpy="0 0 0" xyz="0 0 0.035"/>
      <mass value="0.3"/>
      <inertia ixx="0.0003581" ixy="0.0" ixz="0.0" iyy="0.0005287" iyz="0.0" izz="0.000191"/>
    </inertial>
    <visual>
      <origin rpy="0 0 0" xyz="0 0 0"/>
      <geometry name="lh_palm_visual">
        <mesh filename="package://sr_description/meshes/components/palm/palm_E3M5.dae" scale="-0.001 0.001 0.001"/>
      </geometry>
      <material name="Grey"/>
    </visual>
    <collision>
      <origin rpy="0 0 0" xyz="-0.011 0.0085 0.038"/>
      <geometry name="lh_palm_collision_geom">
        <box size="0.062 0.007 0.098"/>
      </geometry>
    </collision>
    <collision>
      <origin rpy="0 0 0" xyz="0.002 -0.0035 0.038"/>
      <geometry>
        <box size="0.036 0.017 0.098"/>
      </geometry>
    </collision>
    <!-- palm complement below first finger -->
    <collision>
      <origin rpy="0 0 0" xyz="-0.029 -0.0035 0.082"/>
      <geometry>
        <box size="0.026 0.017 0.010"/>
      </geometry>
    </collision>
    <collision>
      <origin rpy="0.2 0 -0.25" xyz="-0.0265 -0.001 0.070"/>
      <geometry>
        <box size="0.026 0.014 0.018"/>
      </geometry>
    </collision>
    <!-- thumb pulp side -->
    <collision>
      <origin rpy="0 0 0" xyz="-0.0315 -0.0085 0.001"/>
      <geometry>
        <box size="0.021 0.027 0.024"/>
      </geometry>
    </collision>
    <!-- thumb pulp central -->
    <collision>
      <origin rpy="0 0 0.48" xyz="-0.0125 -0.015 0.009"/>
      <geometry>
        <box size="0.022 0.005 0.040"/>
      </geometry>
    </collision>
    <!-- above middle finger-->
    <collision>
      <origin rpy="0 0 0" xyz="-0.011 0 0.089"/>
      <geometry>
        <box size="0.018 0.024 0.004"/>
      </geometry>
    </collision>
    <!-- metacarpal side-->
    <collision>
      <origin rpy="0 0 0" xyz="0.03 0 0.009"/>
      <geometry>
        <box size="0.020 0.024 0.040"/>
      </geometry>
    </collision>
  </link>
  <link name="lh_imu"/>
  <joint name="lh_palm_to_imu" type="fixed">
    <parent link="lh_palm"/>
    <child link="lh_imu"/>
    <origin rpy="-1.5707963 3.141592 0.0" xyz="0.01785 0.00765 0.049125"/>
  </joint>
  <transmission name="lh_palm_transmission">
    <type>sr_mechanism_model/SimpleTransmission</type>
    <actuator name="lh_WRJ1">
      <mechanicalReduction>1</mechanicalReduction>
    </actuator>
    <joint name="lh_WRJ1">
      <hardwareInterface>EffortJointInterface</hardwareInterface>
      <hardwareInterface>PositionJointInterface</hardwareInterface>
    </joint>
  </transmission>
  <gazebo reference="lh_palm">
  </gazebo>
  <link name="lh_ffknuckle">
    <inertial>
      <origin rpy="0 0 0" xyz="0 0 0"/>
      <mass value="0.008"/>
      <inertia ixx="0.00000026" ixy="0.0" ixz="0.0" iyy="0.00000026" iyz="0.0" izz="0.00000032"/>
    </inertial>
    <visual>
      <origin rpy="0 0 0" xyz="0 0 0.0005"/>
      <geometry name="lh_ffknuckle_visual">
        <mesh filename="package://sr_description/meshes/components/f_knuckle/f_knuckle_E3M5.dae" scale="0.001 0.001 0.001"/>
      </geometry>
      <material name="LightGrey"/>
    </visual>
    <collision>
      <origin rpy="0 1.5708 0" xyz="0 0 0"/>
      <geometry name="lh_ffknuckle_collision_geom">
        <cylinder length="0.014" radius="0.007"/>
      </geometry>
    </collision>
  </link>
  <joint name="lh_FFJ4" type="revolute">
    <parent link="lh_palm"/>
    <child link="lh_ffknuckle"/>
    <!--<origin xyz="0.033 0 0.095" rpy="0 0 0" />-->
    <origin rpy="0 0 0" xyz="-0.033 0 0.095"/>
    <axis xyz="0 1 0"/>
    <limit effort="2" lower="-0.3490658503988659" upper="0.3490658503988659" velocity="2.0"/>
    <dynamics damping="0.1"/>
  </joint>
  <gazebo reference="lh_FFJ4">
    <provideFeedback>1</provideFeedback>
    <implicitSpringDamper>1</implicitSpringDamper>
  </gazebo>
  <transmission name="lh_ffknuckle_transmission">
    <type>sr_mechanism_model/SimpleTransmission</type>
    <actuator name="lh_FFJ4">
      <mechanicalReduction>1</mechanicalReduction>
    </actuator>
    <joint name="lh_FFJ4">
      <hardwareInterface>EffortJointInterface</hardwareInterface>
      <hardwareInterface>PositionJointInterface</hardwareInterface>
    </joint>
  </transmission>
  <gazebo reference="lh_ffknuckle">
    <!-- knuckle is not highly exposed, so bumper is not useful -->
    <material>Gazebo/Grey</material>
  </gazebo>
  <link name="lh_ffproximal">
    <inertial>
      <mass value="0.030"/>
      <origin xyz="0 0 0.0225"/>
      <inertia ixx="0.0000098" ixy="0.0" ixz="0.0" iyy="0.00001" iyz="0.0" izz="0.0000018"/>
    </inertial>
    <visual>
      <origin rpy="0 0 0" xyz="0 0 0"/>
      <geometry name="lh_ffproximal_visual">
        <mesh filename="package://sr_description/meshes/components/f_proximal/f_proximal_E3M5.dae" scale="0.001 0.001 0.001"/>
      </geometry>
      <material name="Grey"/>
    </visual>
    <collision>
      <origin rpy="0 0 0" xyz="0 0 0.025"/>
      <geometry name="lh_ffproximal_collision_geom">
        <cylinder length="0.040" radius="0.007"/>
      </geometry>
    </collision>
  </link>
  <joint name="lh_FFJ3" type="revolute">
    <parent link="lh_ffknuckle"/>
    <child link="lh_ffproximal"/>
    <origin rpy="0 0 0" xyz="0 0 0"/>
    <axis xyz="1 0 0"/>
    <limit effort="2" lower="0" upper="1.5707963267948966" velocity="2.0"/>
    <dynamics damping="0.1"/>
  </joint>
  <gazebo reference="lh_FFJ3">
    <provideFeedback>1</provideFeedback>
    <implicitSpringDamper>1</implicitSpringDamper>
  </gazebo>
  <transmission name="lh_ffproximal_transmission">
    <type>sr_mechanism_model/SimpleTransmission</type>
    <actuator name="lh_FFJ3">
      <mechanicalReduction>1</mechanicalReduction>
    </actuator>
    <joint name="lh_FFJ3">
      <hardwareInterface>EffortJointInterface</hardwareInterface>
      <hardwareInterface>PositionJointInterface</hardwareInterface>
    </joint>
  </transmission>
  <gazebo reference="lh_ffproximal">
    <selfCollide>true</selfCollide>
  </gazebo>
  <link name="lh_ffmiddle">
    <inertial>
      <origin rpy="0 0 0" xyz="0 0 0.0125"/>
      <mass value="0.017"/>
      <inertia ixx="0.0000026" ixy="0.0" ixz="0.0" iyy="0.0000027" iyz="0.0" izz="0.00000087"/>
    </inertial>
    <visual>
      <origin rpy="0 0 0" xyz="0 0 0"/>
      <geometry name="lh_ffmiddle_visual">
        <mesh filename="package://sr_description/meshes/components/f_middle/f_middle_E3M5.dae" scale="0.001 0.001 0.001"/>
      </geometry>
      <material name="Grey"/>
    </visual>
    <collision>
      <origin rpy="0 0 0" xyz="0 0 0.0125"/>
      <geometry name="lh_ffmiddle_collision_geom">
        <cylinder length="0.025" radius="0.007"/>
      </geometry>
    </collision>
    <collision>
      <origin rpy="0 0 0" xyz="0 0 0.0"/>
      <geometry>
        <sphere radius="0.007"/>
      </geometry>
    </collision>
    <collision>
      <origin rpy="0 0 0" xyz="0 0 0.025"/>
      <geometry>
        <sphere radius="0.007"/>
      </geometry>
    </collision>
  </link>
  <joint name="lh_FFJ2" type="revolute">
    <parent link="lh_ffproximal"/>
    <child link="lh_ffmiddle"/>
    <origin rpy="0 0 0" xyz="0 0 0.045"/>
    <axis xyz="1 0 0"/>
    <limit effort="2" lower="0" upper="1.5707963267948966" velocity="2.0"/>
    <dynamics damping="0.1"/>
  </joint>
  <gazebo reference="lh_FFJ2">
    <provideFeedback>1</provideFeedback>
    <implicitSpringDamper>1</implicitSpringDamper>
  </gazebo>
  <transmission name="lh_ffmiddle_transmission">
    <type>sr_mechanism_model/J0Transmission</type>
    <actuator name="lh_FFJ0">
      <mechanicalReduction>1</mechanicalReduction>
    </actuator>
    <joint name="lh_FFJ1">
      <hardwareInterface>EffortJointInterface</hardwareInterface>
      <hardwareInterface>PositionJointInterface</hardwareInterface>
    </joint>
  </transmission>
  <gazebo reference="lh_ffmiddle">
    <selfCollide>true</selfCollide>
  </gazebo>
  <link name="lh_ffdistal">
    <inertial>
      <mass value="0.012"/>
      <origin xyz="0 0 0.012"/>
      <inertia ixx="0.00000094" ixy="0.0" ixz="0.0" iyy="0.0000011" iyz="0.0" izz="0.00000053"/>
    </inertial>
    <visual>
      <origin rpy="0 0 0" xyz="0 0 0"/>
      <geometry name="lh_ffdistal_visual">
        <mesh filename="package://sr_description/meshes/components/f_distal/pst/f_distal_pst.dae" scale="0.001 0.001 0.001"/>
      </geometry>
    </visual>
    <collision>
      <origin rpy="0 0 0" xyz="0 0 0"/>
      <geometry name="lh_ffdistal_collision_geom">
        <mesh filename="package://sr_description/meshes/components/f_distal/pst/f_distal_pst.dae" scale="0.001 0.001 0.001"/>
      </geometry>
    </collision>
  </link>
  <joint name="lh_FFJ1" type="revolute">
    <parent link="lh_ffmiddle"/>
    <child link="lh_ffdistal"/>
    <origin rpy="0 0 0" xyz="0 0 0.025"/>
    <axis xyz="1 0 0"/>
    <!-- standard distal joint -->
    <limit effort="2" lower="0" upper="1.5707963267948966" velocity="2.0"/>
    <dynamics damping="0.1"/>
  </joint>
  <gazebo reference="lh_FFJ1">
    <provideFeedback>1</provideFeedback>
    <implicitSpringDamper>1</implicitSpringDamper>
  </gazebo>
  <link name="lh_fftip">
    <inertial>
      <mass value="0.001"/>
      <inertia ixx="0.0" ixy="0.0" ixz="0.0" iyy="0.0" iyz="0.0" izz="0.0"/>
    </inertial>
  </link>
  <joint name="lh_FFtip" type="fixed">
    <parent link="lh_ffdistal"/>
    <child link="lh_fftip"/>
    <origin rpy="0 0 0" xyz="0 0 0.026"/>
  </joint>
  <gazebo reference="lh_ffdistal">
    <sensor name="lh_ffdistal_contact" type="contact">
      <always_on>1</always_on>
      <update_rate>1000.0</update_rate>
      <contact>
        <collision>lh_ffdistal_collision</collision>
        <topic>lh_ffdistal_collision</topic>
      </contact>
      <plugin filename="libgazebo_ros_bumper.so" name="lh_ffdistal_gazebo_ros_bumper_controller">
        <alwaysOn>true</alwaysOn>
        <frameName>lh_ffdistal</frameName>
        <updateRate>100.0</updateRate>
        <bumperTopicName>contacts/lh_ff/distal</bumperTopicName>
      </plugin>
    </sensor>
    <mu1 value="500.0"/>
    <mu2 value="500.0"/>
    <kp value="10000000.0"/>
    <kd value="1.0"/>
    <selfCollide>true</selfCollide>
  </gazebo>
  <link name="lh_mfknuckle">
    <inertial>
      <origin rpy="0 0 0" xyz="0 0 0"/>
      <mass value="0.008"/>
      <inertia ixx="0.00000026" ixy="0.0" ixz="0.0" iyy="0.00000026" iyz="0.0" izz="0.00000032"/>
    </inertial>
    <visual>
      <origin rpy="0 0 0" xyz="0 0 0.0005"/>
      <geometry name="lh_mfknuckle_visual">
        <mesh filename="package://sr_description/meshes/components/f_knuckle/f_knuckle_E3M5.dae" scale="0.001 0.001 0.001"/>
      </geometry>
      <material name="LightGrey"/>
    </visual>
    <collision>
      <origin rpy="0 1.5708 0" xyz="0 0 0"/>
      <geometry name="lh_mfknuckle_collision_geom">
        <cylinder length="0.014" radius="0.007"/>
      </geometry>
    </collision>
  </link>
  <joint name="lh_MFJ4" type="revolute">
    <parent link="lh_palm"/>
    <child link="lh_mfknuckle"/>
    <!--<origin xyz="0.033 0 0.095" rpy="0 0 0" />-->
    <origin rpy="0 0 0" xyz="-0.011 0 0.099"/>
    <axis xyz="0 1 0"/>
    <limit effort="2" lower="-0.3490658503988659" upper="0.3490658503988659" velocity="2.0"/>
    <dynamics damping="0.1"/>
  </joint>
  <gazebo reference="lh_MFJ4">
    <provideFeedback>1</provideFeedback>
    <implicitSpringDamper>1</implicitSpringDamper>
  </gazebo>
  <transmission name="lh_mfknuckle_transmission">
    <type>sr_mechanism_model/SimpleTransmission</type>
    <actuator name="lh_MFJ4">
      <mechanicalReduction>1</mechanicalReduction>
    </actuator>
    <joint name="lh_MFJ4">
      <hardwareInterface>EffortJointInterface</hardwareInterface>
      <hardwareInterface>PositionJointInterface</hardwareInterface>
    </joint>
  </transmission>
  <gazebo reference="lh_mfknuckle">
    <!-- knuckle is not highly exposed, so bumper is not useful -->
    <material>Gazebo/Grey</material>
  </gazebo>
  <link name="lh_mfproximal">
    <inertial>
      <mass value="0.030"/>
      <origin xyz="0 0 0.0225"/>
      <inertia ixx="0.0000098" ixy="0.0" ixz="0.0" iyy="0.00001" iyz="0.0" izz="0.0000018"/>
    </inertial>
    <visual>
      <origin rpy="0 0 0" xyz="0 0 0"/>
      <geometry name="lh_mfproximal_visual">
        <mesh filename="package://sr_description/meshes/components/f_proximal/f_proximal_E3M5.dae" scale="0.001 0.001 0.001"/>
      </geometry>
      <material name="Grey"/>
    </visual>
    <collision>
      <origin rpy="0 0 0" xyz="0 0 0.025"/>
      <geometry name="lh_mfproximal_collision_geom">
        <cylinder length="0.040" radius="0.007"/>
      </geometry>
    </collision>
  </link>
  <joint name="lh_MFJ3" type="revolute">
    <parent link="lh_mfknuckle"/>
    <child link="lh_mfproximal"/>
    <origin rpy="0 0 0" xyz="0 0 0"/>
    <axis xyz="1 0 0"/>
    <limit effort="2" lower="0" upper="1.5707963267948966" velocity="2.0"/>
    <dynamics damping="0.1"/>
  </joint>
  <gazebo reference="lh_MFJ3">
    <provideFeedback>1</provideFeedback>
    <implicitSpringDamper>1</implicitSpringDamper>
  </gazebo>
  <transmission name="lh_mfproximal_transmission">
    <type>sr_mechanism_model/SimpleTransmission</type>
    <actuator name="lh_MFJ3">
      <mechanicalReduction>1</mechanicalReduction>
    </actuator>
    <joint name="lh_MFJ3">
      <hardwareInterface>EffortJointInterface</hardwareInterface>
      <hardwareInterface>PositionJointInterface</hardwareInterface>
    </joint>
  </transmission>
  <gazebo reference="lh_mfproximal">
    <selfCollide>true</selfCollide>
  </gazebo>
  <link name="lh_mfmiddle">
    <inertial>
      <origin rpy="0 0 0" xyz="0 0 0.0125"/>
      <mass value="0.017"/>
      <inertia ixx="0.0000026" ixy="0.0" ixz="0.0" iyy="0.0000027" iyz="0.0" izz="0.00000087"/>
    </inertial>
    <visual>
      <origin rpy="0 0 0" xyz="0 0 0"/>
      <geometry name="lh_mfmiddle_visual">
        <mesh filename="package://sr_description/meshes/components/f_middle/f_middle_E3M5.dae" scale="0.001 0.001 0.001"/>
      </geometry>
      <material name="Grey"/>
    </visual>
    <collision>
      <origin rpy="0 0 0" xyz="0 0 0.0125"/>
      <geometry name="lh_mfmiddle_collision_geom">
        <cylinder length="0.025" radius="0.007"/>
      </geometry>
    </collision>
    <collision>
      <origin rpy="0 0 0" xyz="0 0 0.0"/>
      <geometry>
        <sphere radius="0.007"/>
      </geometry>
    </collision>
    <collision>
      <origin rpy="0 0 0" xyz="0 0 0.025"/>
      <geometry>
        <sphere radius="0.007"/>
      </geometry>
    </collision>
  </link>
  <joint name="lh_MFJ2" type="revolute">
    <parent link="lh_mfproximal"/>
    <child link="lh_mfmiddle"/>
    <origin rpy="0 0 0" xyz="0 0 0.045"/>
    <axis xyz="1 0 0"/>
    <limit effort="2" lower="0" upper="1.5707963267948966" velocity="2.0"/>
    <dynamics damping="0.1"/>
  </joint>
  <gazebo reference="lh_MFJ2">
    <provideFeedback>1</provideFeedback>
    <implicitSpringDamper>1</implicitSpringDamper>
  </gazebo>
  <transmission name="lh_mfmiddle_transmission">
    <type>sr_mechanism_model/J0Transmission</type>
    <actuator name="lh_MFJ0">
      <mechanicalReduction>1</mechanicalReduction>
    </actuator>
    <joint name="lh_MFJ1">
      <hardwareInterface>EffortJointInterface</hardwareInterface>
      <hardwareInterface>PositionJointInterface</hardwareInterface>
    </joint>
  </transmission>
  <gazebo reference="lh_mfmiddle">
    <selfCollide>true</selfCollide>
  </gazebo>
  <link name="lh_mfdistal">
    <inertial>
      <mass value="0.012"/>
      <origin xyz="0 0 0.012"/>
      <inertia ixx="0.00000094" ixy="0.0" ixz="0.0" iyy="0.0000011" iyz="0.0" izz="0.00000053"/>
    </inertial>
    <visual>
      <origin rpy="0 0 0" xyz="0 0 0"/>
      <geometry name="lh_mfdistal_visual">
        <mesh filename="package://sr_description/meshes/components/f_distal/pst/f_distal_pst.dae" scale="0.001 0.001 0.001"/>
      </geometry>
    </visual>
    <collision>
      <origin rpy="0 0 0" xyz="0 0 0"/>
      <geometry name="lh_mfdistal_collision_geom">
        <mesh filename="package://sr_description/meshes/components/f_distal/pst/f_distal_pst.dae" scale="0.001 0.001 0.001"/>
      </geometry>
    </collision>
  </link>
  <joint name="lh_MFJ1" type="revolute">
    <parent link="lh_mfmiddle"/>
    <child link="lh_mfdistal"/>
    <origin rpy="0 0 0" xyz="0 0 0.025"/>
    <axis xyz="1 0 0"/>
    <!-- standard distal joint -->
    <limit effort="2" lower="0" upper="1.5707963267948966" velocity="2.0"/>
    <dynamics damping="0.1"/>
  </joint>
  <gazebo reference="lh_MFJ1">
    <provideFeedback>1</provideFeedback>
    <implicitSpringDamper>1</implicitSpringDamper>
  </gazebo>
  <link name="lh_mftip">
    <inertial>
      <mass value="0.001"/>
      <inertia ixx="0.0" ixy="0.0" ixz="0.0" iyy="0.0" iyz="0.0" izz="0.0"/>
    </inertial>
  </link>
  <joint name="lh_MFtip" type="fixed">
    <parent link="lh_mfdistal"/>
    <child link="lh_mftip"/>
    <origin rpy="0 0 0" xyz="0 0 0.026"/>
  </joint>
  <gazebo reference="lh_mfdistal">
    <sensor name="lh_mfdistal_contact" type="contact">
      <always_on>1</always_on>
      <update_rate>1000.0</update_rate>
      <contact>
        <collision>lh_mfdistal_collision</collision>
        <topic>lh_mfdistal_collision</topic>
      </contact>
      <plugin filename="libgazebo_ros_bumper.so" name="lh_mfdistal_gazebo_ros_bumper_controller">
        <alwaysOn>true</alwaysOn>
        <frameName>lh_mfdistal</frameName>
        <updateRate>100.0</updateRate>
        <bumperTopicName>contacts/lh_mf/distal</bumperTopicName>
      </plugin>
    </sensor>
    <mu1 value="500.0"/>
    <mu2 value="500.0"/>
    <kp value="10000000.0"/>
    <kd value="1.0"/>
    <selfCollide>true</selfCollide>
  </gazebo>
  <link name="lh_rfknuckle">
    <inertial>
      <origin rpy="0 0 0" xyz="0 0 0"/>
      <mass value="0.008"/>
      <inertia ixx="0.00000026" ixy="0.0" ixz="0.0" iyy="0.00000026" iyz="0.0" izz="0.00000032"/>
    </inertial>
    <visual>
      <origin rpy="0 0 0" xyz="0 0 0.0005"/>
      <geometry name="lh_rfknuckle_visual">
        <mesh filename="package://sr_description/meshes/components/f_knuckle/f_knuckle_E3M5.dae" scale="0.001 0.001 0.001"/>
      </geometry>
      <material name="LightGrey"/>
    </visual>
    <collision>
      <origin rpy="0 1.5708 0" xyz="0 0 0"/>
      <geometry name="lh_rfknuckle_collision_geom">
        <cylinder length="0.014" radius="0.007"/>
      </geometry>
    </collision>
  </link>
  <joint name="lh_RFJ4" type="revolute">
    <parent link="lh_palm"/>
    <child link="lh_rfknuckle"/>
    <!--<origin xyz="0.033 0 0.095" rpy="0 0 0" />-->
    <origin rpy="0 0 0" xyz="0.011 0 0.095"/>
    <axis xyz="0 -1 0"/>
    <limit effort="2" lower="-0.3490658503988659" upper="0.3490658503988659" velocity="2.0"/>
    <dynamics damping="0.1"/>
  </joint>
  <gazebo reference="lh_RFJ4">
    <provideFeedback>1</provideFeedback>
    <implicitSpringDamper>1</implicitSpringDamper>
  </gazebo>
  <transmission name="lh_rfknuckle_transmission">
    <type>sr_mechanism_model/SimpleTransmission</type>
    <actuator name="lh_RFJ4">
      <mechanicalReduction>1</mechanicalReduction>
    </actuator>
    <joint name="lh_RFJ4">
      <hardwareInterface>EffortJointInterface</hardwareInterface>
      <hardwareInterface>PositionJointInterface</hardwareInterface>
    </joint>
  </transmission>
  <gazebo reference="lh_rfknuckle">
    <!-- knuckle is not highly exposed, so bumper is not useful -->
    <material>Gazebo/Grey</material>
  </gazebo>
  <link name="lh_rfproximal">
    <inertial>
      <mass value="0.030"/>
      <origin xyz="0 0 0.0225"/>
      <inertia ixx="0.0000098" ixy="0.0" ixz="0.0" iyy="0.00001" iyz="0.0" izz="0.0000018"/>
    </inertial>
    <visual>
      <origin rpy="0 0 0" xyz="0 0 0"/>
      <geometry name="lh_rfproximal_visual">
        <mesh filename="package://sr_description/meshes/components/f_proximal/f_proximal_E3M5.dae" scale="0.001 0.001 0.001"/>
      </geometry>
      <material name="Grey"/>
    </visual>
    <collision>
      <origin rpy="0 0 0" xyz="0 0 0.025"/>
      <geometry name="lh_rfproximal_collision_geom">
        <cylinder length="0.040" radius="0.007"/>
      </geometry>
    </collision>
  </link>
  <joint name="lh_RFJ3" type="revolute">
    <parent link="lh_rfknuckle"/>
    <child link="lh_rfproximal"/>
    <origin rpy="0 0 0" xyz="0 0 0"/>
    <axis xyz="1 0 0"/>
    <limit effort="2" lower="0" upper="1.5707963267948966" velocity="2.0"/>
    <dynamics damping="0.1"/>
  </joint>
  <gazebo reference="lh_RFJ3">
    <provideFeedback>1</provideFeedback>
    <implicitSpringDamper>1</implicitSpringDamper>
  </gazebo>
  <transmission name="lh_rfproximal_transmission">
    <type>sr_mechanism_model/SimpleTransmission</type>
    <actuator name="lh_RFJ3">
      <mechanicalReduction>1</mechanicalReduction>
    </actuator>
    <joint name="lh_RFJ3">
      <hardwareInterface>EffortJointInterface</hardwareInterface>
      <hardwareInterface>PositionJointInterface</hardwareInterface>
    </joint>
  </transmission>
  <gazebo reference="lh_rfproximal">
    <selfCollide>true</selfCollide>
  </gazebo>
  <link name="lh_rfmiddle">
    <inertial>
      <origin rpy="0 0 0" xyz="0 0 0.0125"/>
      <mass value="0.017"/>
      <inertia ixx="0.0000026" ixy="0.0" ixz="0.0" iyy="0.0000027" iyz="0.0" izz="0.00000087"/>
    </inertial>
    <visual>
      <origin rpy="0 0 0" xyz="0 0 0"/>
      <geometry name="lh_rfmiddle_visual">
        <mesh filename="package://sr_description/meshes/components/f_middle/f_middle_E3M5.dae" scale="0.001 0.001 0.001"/>
      </geometry>
      <material name="Grey"/>
    </visual>
    <collision>
      <origin rpy="0 0 0" xyz="0 0 0.0125"/>
      <geometry name="lh_rfmiddle_collision_geom">
        <cylinder length="0.025" radius="0.007"/>
      </geometry>
    </collision>
    <collision>
      <origin rpy="0 0 0" xyz="0 0 0.0"/>
      <geometry>
        <sphere radius="0.007"/>
      </geometry>
    </collision>
    <collision>
      <origin rpy="0 0 0" xyz="0 0 0.025"/>
      <geometry>
        <sphere radius="0.007"/>
      </geometry>
    </collision>
  </link>
  <joint name="lh_RFJ2" type="revolute">
    <parent link="lh_rfproximal"/>
    <child link="lh_rfmiddle"/>
    <origin rpy="0 0 0" xyz="0 0 0.045"/>
    <axis xyz="1 0 0"/>
    <limit effort="2" lower="0" upper="1.5707963267948966" velocity="2.0"/>
    <dynamics damping="0.1"/>
  </joint>
  <gazebo reference="lh_RFJ2">
    <provideFeedback>1</provideFeedback>
    <implicitSpringDamper>1</implicitSpringDamper>
  </gazebo>
  <transmission name="lh_rfmiddle_transmission">
    <type>sr_mechanism_model/J0Transmission</type>
    <actuator name="lh_RFJ0">
      <mechanicalReduction>1</mechanicalReduction>
    </actuator>
    <joint name="lh_RFJ1">
      <hardwareInterface>EffortJointInterface</hardwareInterface>
      <hardwareInterface>PositionJointInterface</hardwareInterface>
    </joint>
  </transmission>
  <gazebo reference="lh_rfmiddle">
    <selfCollide>true</selfCollide>
  </gazebo>
  <link name="lh_rfdistal">
    <inertial>
      <mass value="0.012"/>
      <origin xyz="0 0 0.012"/>
      <inertia ixx="0.00000094" ixy="0.0" ixz="0.0" iyy="0.0000011" iyz="0.0" izz="0.00000053"/>
    </inertial>
    <visual>
      <origin rpy="0 0 0" xyz="0 0 0"/>
      <geometry name="lh_rfdistal_visual">
        <mesh filename="package://sr_description/meshes/components/f_distal/pst/f_distal_pst.dae" scale="0.001 0.001 0.001"/>
      </geometry>
    </visual>
    <collision>
      <origin rpy="0 0 0" xyz="0 0 0"/>
      <geometry name="lh_rfdistal_collision_geom">
        <mesh filename="package://sr_description/meshes/components/f_distal/pst/f_distal_pst.dae" scale="0.001 0.001 0.001"/>
      </geometry>
    </collision>
  </link>
  <joint name="lh_RFJ1" type="revolute">
    <parent link="lh_rfmiddle"/>
    <child link="lh_rfdistal"/>
    <origin rpy="0 0 0" xyz="0 0 0.025"/>
    <axis xyz="1 0 0"/>
    <!-- standard distal joint -->
    <limit effort="2" lower="0" upper="1.5707963267948966" velocity="2.0"/>
    <dynamics damping="0.1"/>
  </joint>
  <gazebo reference="lh_RFJ1">
    <provideFeedback>1</provideFeedback>
    <implicitSpringDamper>1</implicitSpringDamper>
  </gazebo>
  <link name="lh_rftip">
    <inertial>
      <mass value="0.001"/>
      <inertia ixx="0.0" ixy="0.0" ixz="0.0" iyy="0.0" iyz="0.0" izz="0.0"/>
    </inertial>
  </link>
  <joint name="lh_RFtip" type="fixed">
    <parent link="lh_rfdistal"/>
    <child link="lh_rftip"/>
    <origin rpy="0 0 0" xyz="0 0 0.026"/>
  </joint>
  <gazebo reference="lh_rfdistal">
    <sensor name="lh_rfdistal_contact" type="contact">
      <always_on>1</always_on>
      <update_rate>1000.0</update_rate>
      <contact>
        <collision>lh_rfdistal_collision</collision>
        <topic>lh_rfdistal_collision</topic>
      </contact>
      <plugin filename="libgazebo_ros_bumper.so" name="lh_rfdistal_gazebo_ros_bumper_controller">
        <alwaysOn>true</alwaysOn>
        <frameName>lh_rfdistal</frameName>
        <updateRate>100.0</updateRate>
        <bumperTopicName>contacts/lh_rf/distal</bumperTopicName>
      </plugin>
    </sensor>
    <mu1 value="500.0"/>
    <mu2 value="500.0"/>
    <kp value="10000000.0"/>
    <kd value="1.0"/>
    <selfCollide>true</selfCollide>
  </gazebo>
  <link name="lh_lfmetacarpal">
    <inertial>
      <origin rpy="0 -0.9599 0" xyz="-0.03174867647058824 0 0.02235294117647059"/>
      <mass value="0.030"/>
      <inertia ixx="0.0000145" ixy="0.0" ixz="0.0" iyy="0.00001638" iyz="0.0" izz="0.000004272"/>
    </inertial>
    <visual>
      <origin rpy="0 -0.9599 0" xyz="0 0 0"/>
      <geometry name="lh_lfmetacarpal_visual">
        <mesh filename="package://sr_description/meshes/components/lf_metacarpal/lf_metacarpal_E3M5.dae" scale="-0.001 0.001 0.001"/>
      </geometry>
      <material name="Grey"/>
    </visual>
    <collision>
      <origin rpy="0 -0.9599 0" xyz="-0.026986375 0 0.019"/>
      <geometry name="lh_lfmetacarpal_collision_geom">
        <box size="0.018 0.024 0.040"/>
      </geometry>
    </collision>
  </link>
  <joint name="lh_LFJ5" type="revolute">
    <parent link="lh_palm"/>
    <child link="lh_lfmetacarpal"/>
    <origin rpy="0 0.9599 0" xyz="0.033 0 0.02071"/>
    <axis xyz="1 0 0"/>
    <limit effort="2" lower="0" upper="0.7853981633974483" velocity="2.0"/>
    <dynamics damping="0.1"/>
  </joint>
  <gazebo reference="lh_LFJ5">
    <provideFeedback>1</provideFeedback>
    <implicitSpringDamper>1</implicitSpringDamper>
  </gazebo>
  <transmission name="lh_lfmetacarpal_transmission">
    <type>sr_mechanism_model/SimpleTransmission</type>
    <actuator name="lh_LFJ5">
      <mechanicalReduction>1</mechanicalReduction>
    </actuator>
    <joint name="lh_LFJ5">
      <hardwareInterface>EffortJointInterface</hardwareInterface>
      <hardwareInterface>PositionJointInterface</hardwareInterface>
    </joint>
  </transmission>
  <gazebo reference="lh_lfmetacarpal">
    <selfCollide>true</selfCollide>
  </gazebo>
  <link name="lh_lfknuckle">
    <inertial>
      <origin rpy="0 0 0" xyz="0 0 0"/>
      <mass value="0.008"/>
      <inertia ixx="0.00000026" ixy="0.0" ixz="0.0" iyy="0.00000026" iyz="0.0" izz="0.00000032"/>
    </inertial>
    <visual>
      <origin rpy="0 0 0" xyz="0 0 0.0005"/>
      <geometry name="lh_lfknuckle_visual">
        <mesh filename="package://sr_description/meshes/components/f_knuckle/f_knuckle_E3M5.dae" scale="0.001 0.001 0.001"/>
      </geometry>
      <material name="LightGrey"/>
    </visual>
    <collision>
      <origin rpy="0 1.5708 0" xyz="0 0 0"/>
      <geometry name="lh_lfknuckle_collision_geom">
        <cylinder length="0.014" radius="0.007"/>
      </geometry>
    </collision>
  </link>
  <joint name="lh_LFJ4" type="revolute">
    <parent link="lh_lfmetacarpal"/>
    <child link="lh_lfknuckle"/>
    <!--<origin xyz="0.033 0 0.095" rpy="0 0 0" />-->
    <origin rpy="0 -0.9599 0" xyz="-0.05397275 0 0.03779463"/>
    <axis xyz="0 -1 0"/>
    <limit effort="2" lower="-0.3490658503988659" upper="0.3490658503988659" velocity="2.0"/>
    <dynamics damping="0.1"/>
  </joint>
  <gazebo reference="lh_LFJ4">
    <provideFeedback>1</provideFeedback>
    <implicitSpringDamper>1</implicitSpringDamper>
  </gazebo>
  <transmission name="lh_lfknuckle_transmission">
    <type>sr_mechanism_model/SimpleTransmission</type>
    <actuator name="lh_LFJ4">
      <mechanicalReduction>1</mechanicalReduction>
    </actuator>
    <joint name="lh_LFJ4">
      <hardwareInterface>EffortJointInterface</hardwareInterface>
      <hardwareInterface>PositionJointInterface</hardwareInterface>
    </joint>
  </transmission>
  <gazebo reference="lh_lfknuckle">
    <!-- knuckle is not highly exposed, so bumper is not useful -->
    <material>Gazebo/Grey</material>
  </gazebo>
  <link name="lh_lfproximal">
    <inertial>
      <mass value="0.030"/>
      <origin xyz="0 0 0.0225"/>
      <inertia ixx="0.0000098" ixy="0.0" ixz="0.0" iyy="0.00001" iyz="0.0" izz="0.0000018"/>
    </inertial>
    <visual>
      <origin rpy="0 0 0" xyz="0 0 0"/>
      <geometry name="lh_lfproximal_visual">
        <mesh filename="package://sr_description/meshes/components/f_proximal/f_proximal_E3M5.dae" scale="0.001 0.001 0.001"/>
      </geometry>
      <material name="Grey"/>
    </visual>
    <collision>
      <origin rpy="0 0 0" xyz="0 0 0.025"/>
      <geometry name="lh_lfproximal_collision_geom">
        <cylinder length="0.040" radius="0.007"/>
      </geometry>
    </collision>
  </link>
  <joint name="lh_LFJ3" type="revolute">
    <parent link="lh_lfknuckle"/>
    <child link="lh_lfproximal"/>
    <origin rpy="0 0 0" xyz="0 0 0"/>
    <axis xyz="1 0 0"/>
    <limit effort="2" lower="0" upper="1.5707963267948966" velocity="2.0"/>
    <dynamics damping="0.1"/>
  </joint>
  <gazebo reference="lh_LFJ3">
    <provideFeedback>1</provideFeedback>
    <implicitSpringDamper>1</implicitSpringDamper>
  </gazebo>
  <transmission name="lh_lfproximal_transmission">
    <type>sr_mechanism_model/SimpleTransmission</type>
    <actuator name="lh_LFJ3">
      <mechanicalReduction>1</mechanicalReduction>
    </actuator>
    <joint name="lh_LFJ3">
      <hardwareInterface>EffortJointInterface</hardwareInterface>
      <hardwareInterface>PositionJointInterface</hardwareInterface>
    </joint>
  </transmission>
  <gazebo reference="lh_lfproximal">
    <selfCollide>true</selfCollide>
  </gazebo>
  <link name="lh_lfmiddle">
    <inertial>
      <origin rpy="0 0 0" xyz="0 0 0.0125"/>
      <mass value="0.017"/>
      <inertia ixx="0.0000026" ixy="0.0" ixz="0.0" iyy="0.0000027" iyz="0.0" izz="0.00000087"/>
    </inertial>
    <visual>
      <origin rpy="0 0 0" xyz="0 0 0"/>
      <geometry name="lh_lfmiddle_visual">
        <mesh filename="package://sr_description/meshes/components/f_middle/f_middle_E3M5.dae" scale="0.001 0.001 0.001"/>
      </geometry>
      <material name="Grey"/>
    </visual>
    <collision>
      <origin rpy="0 0 0" xyz="0 0 0.0125"/>
      <geometry name="lh_lfmiddle_collision_geom">
        <cylinder length="0.025" radius="0.007"/>
      </geometry>
    </collision>
    <collision>
      <origin rpy="0 0 0" xyz="0 0 0.0"/>
      <geometry>
        <sphere radius="0.007"/>
      </geometry>
    </collision>
    <collision>
      <origin rpy="0 0 0" xyz="0 0 0.025"/>
      <geometry>
        <sphere radius="0.007"/>
      </geometry>
    </collision>
  </link>
  <joint name="lh_LFJ2" type="revolute">
    <parent link="lh_lfproximal"/>
    <child link="lh_lfmiddle"/>
    <origin rpy="0 0 0" xyz="0 0 0.045"/>
    <axis xyz="1 0 0"/>
    <limit effort="2" lower="0" upper="1.5707963267948966" velocity="2.0"/>
    <dynamics damping="0.1"/>
  </joint>
  <gazebo reference="lh_LFJ2">
    <provideFeedback>1</provideFeedback>
    <implicitSpringDamper>1</implicitSpringDamper>
  </gazebo>
  <transmission name="lh_lfmiddle_transmission">
    <type>sr_mechanism_model/J0Transmission</type>
    <actuator name="lh_LFJ0">
      <mechanicalReduction>1</mechanicalReduction>
    </actuator>
    <joint name="lh_LFJ1">
      <hardwareInterface>EffortJointInterface</hardwareInterface>
      <hardwareInterface>PositionJointInterface</hardwareInterface>
    </joint>
  </transmission>
  <gazebo reference="lh_lfmiddle">
    <selfCollide>true</selfCollide>
  </gazebo>
  <link name="lh_lfdistal">
    <inertial>
      <mass value="0.012"/>
      <origin xyz="0 0 0.012"/>
      <inertia ixx="0.00000094" ixy="0.0" ixz="0.0" iyy="0.0000011" iyz="0.0" izz="0.00000053"/>
    </inertial>
    <visual>
      <origin rpy="0 0 0" xyz="0 0 0"/>
      <geometry name="lh_lfdistal_visual">
        <mesh filename="package://sr_description/meshes/components/f_distal/pst/f_distal_pst.dae" scale="0.001 0.001 0.001"/>
      </geometry>
    </visual>
    <collision>
      <origin rpy="0 0 0" xyz="0 0 0"/>
      <geometry name="lh_lfdistal_collision_geom">
        <mesh filename="package://sr_description/meshes/components/f_distal/pst/f_distal_pst.dae" scale="0.001 0.001 0.001"/>
      </geometry>
    </collision>
  </link>
  <joint name="lh_LFJ1" type="revolute">
    <parent link="lh_lfmiddle"/>
    <child link="lh_lfdistal"/>
    <origin rpy="0 0 0" xyz="0 0 0.025"/>
    <axis xyz="1 0 0"/>
    <!-- standard distal joint -->
    <limit effort="2" lower="0" upper="1.5707963267948966" velocity="2.0"/>
    <dynamics damping="0.1"/>
  </joint>
  <gazebo reference="lh_LFJ1">
    <provideFeedback>1</provideFeedback>
    <implicitSpringDamper>1</implicitSpringDamper>
  </gazebo>
  <link name="lh_lftip">
    <inertial>
      <mass value="0.001"/>
      <inertia ixx="0.0" ixy="0.0" ixz="0.0" iyy="0.0" iyz="0.0" izz="0.0"/>
    </inertial>
  </link>
  <joint name="lh_LFtip" type="fixed">
    <parent link="lh_lfdistal"/>
    <child link="lh_lftip"/>
    <origin rpy="0 0 0" xyz="0 0 0.026"/>
  </joint>
  <gazebo reference="lh_lfdistal">
    <sensor name="lh_lfdistal_contact" type="contact">
      <always_on>1</always_on>
      <update_rate>1000.0</update_rate>
      <contact>
        <collision>lh_lfdistal_collision</collision>
        <topic>lh_lfdistal_collision</topic>
      </contact>
      <plugin filename="libgazebo_ros_bumper.so" name="lh_lfdistal_gazebo_ros_bumper_controller">
        <alwaysOn>true</alwaysOn>
        <frameName>lh_lfdistal</frameName>
        <updateRate>100.0</updateRate>
        <bumperTopicName>contacts/lh_lf/distal</bumperTopicName>
      </plugin>
    </sensor>
    <mu1 value="500.0"/>
    <mu2 value="500.0"/>
    <kp value="10000000.0"/>
    <kd value="1.0"/>
    <selfCollide>true</selfCollide>
  </gazebo>
  <link name="lh_thbase">
    <inertial>
      <mass value="0.010"/>
      <origin rpy="0 0 0" xyz="0 0 0"/>
      <inertia ixx="0.00000016" ixy="0.0" ixz="0.0" iyy="0.00000016" iyz="0.0" izz="0.00000016"/>
    </inertial>
    <visual>
      <origin rpy="0 0 0" xyz="0 0 0"/>
      <geometry name="lh_thbase_visual">
        <box size="0.001 0.001 0.001"/>
      </geometry>
      <material name="shadow_thbase_material">
        <color rgba="0.5 0.5 0.5 1.0"/>
      </material>
    </visual>
    <collision>
      <origin rpy="0 0 0" xyz="0 0 0"/>
      <geometry name="lh_thbase_collision_geom">
        <sphere radius="0.011"/>
      </geometry>
    </collision>
  </link>
  <joint name="lh_THJ5" type="revolute">
    <parent link="lh_palm"/>
    <child link="lh_thbase"/>
    <origin rpy="-0.7853981633974483 0 1.5707963267948966" xyz="-0.034 -0.00858 0.029"/>
    <axis xyz="0 0 1"/>
    <limit effort="5.0" lower="-1.0471975511965976" upper="1.0471975511965976" velocity="4.0"/>
    <dynamics damping="0.2"/>
  </joint>
  <gazebo reference="lh_THJ5">
    <provideFeedback>1</provideFeedback>
    <implicitSpringDamper>1</implicitSpringDamper>
  </gazebo>
  <transmission name="lh_thbase_transmission">
    <type>sr_mechanism_model/SimpleTransmission</type>
    <actuator name="lh_THJ5">
      <mechanicalReduction>1</mechanicalReduction>
    </actuator>
    <joint name="lh_THJ5">
      <hardwareInterface>EffortJointInterface</hardwareInterface>
      <hardwareInterface>PositionJointInterface</hardwareInterface>
    </joint>
  </transmission>
  <gazebo reference="lh_thbase">
    <!-- base is inside the proximal and not exposed, so bumper is not needed -->
    <selfCollide>false</selfCollide>
  </gazebo>
  <link name="lh_thproximal">
    <inertial>
      <mass value="0.040"/>
      <origin rpy="0 0 0" xyz="0 0 0.019"/>
      <inertia ixx="0.0000136" ixy="0.0" ixz="0.0" iyy="0.0000136" iyz="0.0" izz="0.00000313"/>
    </inertial>
    <visual>
      <origin rpy="0 0 1.5707963267948966" xyz="0 0 0"/>
      <geometry name="lh_thproximal_visual">
        <mesh filename="package://sr_description/meshes/components/th_proximal/th_proximal_E3M5.dae" scale="0.001 0.001 0.001"/>
      </geometry>
      <material name="shadow_thproximal_material">
        <color rgba="0.2 0.2 0.2 1.0"/>
      </material>
    </visual>
    <collision>
      <origin rpy="0 0 0" xyz="0 0 0.020"/>
      <geometry name="lh_thproximal_collision_geom">
        <cylinder length="0.018" radius="0.012"/>
      </geometry>
    </collision>
  </link>
  <joint name="lh_THJ4" type="revolute">
    <parent link="lh_thbase"/>
    <child link="lh_thproximal"/>
    <origin rpy="0 0 0" xyz="0 0 0"/>
    <axis xyz="0 -1 0"/>
    <limit effort="3" lower="0.0" upper="1.2217304763960306" velocity="4.0"/>
    <dynamics damping="0.2"/>
  </joint>
  <gazebo reference="lh_THJ4">
    <provideFeedback>1</provideFeedback>
    <implicitSpringDamper>1</implicitSpringDamper>
  </gazebo>
  <transmission name="lh_thproximal_transmission">
    <type>sr_mechanism_model/SimpleTransmission</type>
    <actuator name="lh_THJ4">
      <mechanicalReduction>1</mechanicalReduction>
    </actuator>
    <joint name="lh_THJ4">
      <hardwareInterface>EffortJointInterface</hardwareInterface>
      <hardwareInterface>PositionJointInterface</hardwareInterface>
    </joint>
  </transmission>
  <gazebo reference="lh_thproximal">
    <selfCollide>false</selfCollide>
  </gazebo>
  <link name="lh_thhub">
    <inertial>
      <mass value="0.005"/>
      <origin rpy="0 0 0" xyz="0 0 0"/>
      <inertia ixx="0.000001" ixy="0.0" ixz="0.0" iyy="0.000001" iyz="0.0" izz="0.0000003"/>
    </inertial>
    <visual>
      <origin rpy="0 0 0" xyz="0 0 0"/>
      <geometry name="lh_thhub_visual">
        <box size="0.001 0.001 0.001"/>
      </geometry>
      <material name="shadow_thhub_material">
        <color rgba="0.7 0.7 0.7 1.0"/>
      </material>
    </visual>
    <collision>
      <origin rpy="0 0 0" xyz="0 0 0"/>
      <geometry name="lh_thhub_collision_geom">
        <sphere radius="0.010"/>
      </geometry>
    </collision>
  </link>
  <joint name="lh_THJ3" type="revolute">
    <parent link="lh_thproximal"/>
    <child link="lh_thhub"/>
    <origin rpy="0 0 0" xyz="0 0 0.038"/>
    <axis xyz="0 -1 0"/>
    <limit effort="2.0" lower="0" upper="0.20943951023931953" velocity="4.0"/>
    <dynamics damping="0.2"/>
  </joint>
  <gazebo reference="lh_THJ3">
    <provideFeedback>1</provideFeedback>
    <implicitSpringDamper>1</implicitSpringDamper>
  </gazebo>
  <transmission name="lh_thhub_transmission">
    <type>sr_mechanism_model/SimpleTransmission</type>
    <actuator name="lh_THJ3">
      <mechanicalReduction>1</mechanicalReduction>
    </actuator>
    <joint name="lh_THJ3">
      <hardwareInterface>EffortJointInterface</hardwareInterface>
      <hardwareInterface>PositionJointInterface</hardwareInterface>
    </joint>
  </transmission>
  <gazebo reference="lh_thhub">
    <!-- hub is inside the proximal and not exposed, so bumper is not needed -->
    <selfCollide>false</selfCollide>
  </gazebo>
  <link name="lh_thmiddle">
    <inertial>
      <mass value="0.020"/>
      <origin rpy="0 0 0" xyz="0 0 0.016"/>
      <inertia ixx="0.0000051" ixy="0.0" ixz="0.0" iyy="0.0000051" iyz="0.0" izz="0.00000121"/>
    </inertial>
    <visual>
      <origin rpy="0 0 1.5707963267948966" xyz="0 0 0"/>
      <geometry name="lh_thmiddle_visual">
        <mesh filename="package://sr_description/meshes/components/th_middle/th_middle_E3M5.dae" scale="0.001 0.001 0.001"/>
      </geometry>
      <material name="shadow_thmiddle_material">
        <color rgba="0.2 0.2 0.2 1.0"/>
      </material>
    </visual>
    <collision>
      <origin rpy="0 0 0" xyz="0 0 0.012"/>
      <geometry name="lh_thmiddle_collision_geom">
        <cylinder length="0.018" radius="0.011"/>
      </geometry>
    </collision>
    <collision>
      <origin rpy="0 0 0" xyz="0 0 0.019"/>
      <geometry>
        <sphere radius="0.011"/>
      </geometry>
    </collision>
    <collision>
      <origin rpy="0 1.5708 0" xyz="0 0 0.032"/>
      <geometry>
        <cylinder length="0.014" radius="0.010"/>
      </geometry>
    </collision>
  </link>
  <joint name="lh_THJ2" type="revolute">
    <parent link="lh_thhub"/>
    <child link="lh_thmiddle"/>
    <origin rpy="0 0 0" xyz="0 0 0"/>
    <axis xyz="1 0 0"/>
    <limit effort="2.0" lower="0" upper="0.6981317007977318" velocity="2.0"/>
    <dynamics damping="0.1"/>
  </joint>
  <gazebo reference="lh_THJ2">
    <provideFeedback>1</provideFeedback>
    <implicitSpringDamper>1</implicitSpringDamper>
  </gazebo>
  <transmission name="lh_thmiddle_transmission">
    <type>sr_mechanism_model/SimpleTransmission</type>
    <actuator name="lh_THJ2">
      <mechanicalReduction>1</mechanicalReduction>
    </actuator>
    <joint name="lh_THJ2">
      <hardwareInterface>EffortJointInterface</hardwareInterface>
      <hardwareInterface>PositionJointInterface</hardwareInterface>
    </joint>
  </transmission>
  <gazebo reference="lh_thmiddle">
  </gazebo>
  <!-- common -->
  <link name="lh_thdistal">
    <inertial>
      <mass value="0.016"/>
      <origin rpy="0 0 0" xyz="0 0 0.01375"/>
      <inertia ixx="0.0000021" ixy="0.0" ixz="0.0" iyy="0.0000022" iyz="0.0" izz="0.000001"/>
    </inertial>
    <visual>
      <origin rpy="0 0 0" xyz="0 0 0"/>
      <geometry name="lh_thdistal_visual">
        <mesh filename="package://sr_description/meshes/components/th_distal/pst/th_distal_pst.dae" scale="0.001 0.001 0.001"/>
      </geometry>
      <material name="shadow_thmiddle_material">
        <color rgba="0.2 0.2 0.2 1.0"/>
      </material>
    </visual>
    <collision>
      <origin rpy="0 0 0" xyz="0 0 0"/>
      <geometry name="lh_thmiddle_collision_geom">
        <mesh filename="package://sr_description/meshes/components/th_distal/pst/th_distal_pst.dae" scale="0.001 0.001 0.001"/>
      </geometry>
    </collision>
  </link>
  <joint name="lh_THJ1" type="revolute">
    <parent link="lh_thmiddle"/>
    <child link="lh_thdistal"/>
    <origin rpy="0 0 0" xyz="0 0 0.032"/>
    <axis xyz="1 0 0"/>
    <limit effort="1.0" lower="0" upper="1.5707963267948966" velocity="4.0"/>
    <dynamics damping="0.2"/>
  </joint>
  <gazebo reference="lh_THJ1">
    <provideFeedback>1</provideFeedback>
    <implicitSpringDamper>1</implicitSpringDamper>
  </gazebo>
  <link name="lh_thtip">
    <inertial>
      <mass value="0.001"/>
      <inertia ixx="0.0" ixy="0.0" ixz="0.0" iyy="0.0" iyz="0.0" izz="0.0"/>
    </inertial>
  </link>
  <joint name="lh_thtip" type="fixed">
    <parent link="lh_thdistal"/>
    <child link="lh_thtip"/>
    <origin rpy="0 0 0" xyz="0 0 0.0275"/>
  </joint>
  <gazebo reference="lh_thdistal">
    <sensor name="lh_thdistal_contact" type="contact">
      <always_on>1</always_on>
      <update_rate>1000.0</update_rate>
      <contact>
        <collision>lh_thdistal_collision</collision>
        <topic>lh_thdistal_collision</topic>
      </contact>
      <plugin filename="libgazebo_ros_bumper.so" name="lh_thdistal_gazebo_ros_bumper_controller">
        <alwaysOn>true</alwaysOn>
        <frameName>lh_thdistal</frameName>
        <updateRate>100.0</updateRate>
        <bumperTopicName>contacts/lh_th/distal</bumperTopicName>
      </plugin>
    </sensor>
    <mu1 value="500.0"/>
    <mu2 value="500.0"/>
    <kp value="10000000.0"/>
    <kd value="1.0"/>
    <selfCollide>true</selfCollide>
  </gazebo>
  <transmission name="lh_thdistal_transmission">
    <type>sr_mechanism_model/SimpleTransmission</type>
    <actuator name="lh_THJ1">
      <mechanicalReduction>1</mechanicalReduction>
    </actuator>
    <joint name="lh_THJ1">
      <hardwareInterface>EffortJointInterface</hardwareInterface>
      <hardwareInterface>PositionJointInterface</hardwareInterface>
    </joint>
  </transmission>
  
  
  
  
  
  <link name="Link_waist_pitch">
    <inertial>
      <origin rpy="0 0 0" xyz="-0.00073496 0.049925 -2.9695E-05"/>
      <mass value="2.6964"/>
      <inertia ixx="0.0051971" ixy="-4.37E-05" ixz="3E-07" iyy="0.0047413" iyz="6E-06" izz="0.0061906"/>
    </inertial>
    <visual>
      <origin rpy="0 0 0" xyz="0 0 0"/>
      <geometry>
        <mesh filename="package://azureloong_description/meshes/Link_waist_pitch.STL"/>
      </geometry>
      <material name="">
        <color rgba="0.69804 0.69804 0.69804 1"/>
      </material>
    </visual>
    <collision>
      <origin rpy="0 0 0" xyz="0 0 0"/>
      <geometry>
        <mesh filename="package://azureloong_description/meshes/Link_waist_pitch.STL"/>
      </geometry>
    </collision>
  </link>
  <joint name="J_waist_pitch" type="revolute">
    <origin rpy="0 0 0" xyz="0 -0.06525 0"/>
    <parent link="base_link"/>
    <child link="Link_waist_pitch"/>
    <axis xyz="0 -1 0"/>
    <limit effort="315" lower="-0.29671" upper="0.78540" velocity="3.72"/>
  </joint>
  <link name="Link_waist_roll">
    <inertial>
      <origin rpy="0 0 0" xyz="-0.0037424 -0.001 -0.016856"/>
      <mass value="2.9806"/>
      <inertia ixx="0.0071327" ixy="0" ixz="-0.00358" iyy="0.018825" iyz="0" izz="0.016056"/>
    </inertial>
    <visual>
      <origin rpy="0 0 0" xyz="0 0 0"/>
      <geometry>
        <mesh filename="package://azureloong_description/meshes/Link_waist_roll.STL"/>
      </geometry>
      <material name="">
        <color rgba="0.8902 0.8902 0.91373 1"/>
      </material>
    </visual>
    <collision>
      <origin rpy="0 0 0" xyz="0 0 0"/>
      <geometry>
        <mesh filename="package://azureloong_description/meshes/Link_waist_roll.STL"/>
      </geometry>
    </collision>
  </link>
  <joint name="J_waist_roll" type="revolute">
    <origin rpy="0 0 0" xyz="-0.064 0.0655 0"/>
    <parent link="Link_waist_pitch"/>
    <child link="Link_waist_roll"/>
    <axis xyz="1 0 0"/>
    <limit effort="315" lower="-0.69813" upper="0.69813" velocity="3.72"/>
  </joint>
  <link name="Link_waist_yaw">
    <inertial>
      <origin rpy="0 0 0" xyz="-0.096172 -0.001 -0.057836"/>
      <mass value="7.3588"/>
      <inertia ixx="0.091635" ixy="0" ixz="0.0058036" iyy="0.032766" iyz="0" izz="0.10764"/>
    </inertial>
    <visual>
      <origin rpy="0 0 0" xyz="0 0 0"/>
      <geometry>
        <mesh filename="package://azureloong_description/meshes/Link_waist_yaw.STL"/>
      </geometry>
      <material name="">
        <color rgba="0.8902 0.8902 0.91373 1"/>
      </material>
    </visual>
    <collision>
      <origin rpy="0 0 0" xyz="0 0 0"/>
      <geometry>
        <mesh filename="package://azureloong_description/meshes/Link_waist_yaw.STL"/>
      </geometry>
    </collision>
  </link>
  <joint name="J_waist_yaw" type="revolute">
    <origin rpy="0 0 0" xyz="0.0675 0 -0.098"/>
    <parent link="Link_waist_roll"/>
    <child link="Link_waist_yaw"/>
    <axis xyz="0 0 1"/>
    <limit effort="121" lower="-0.78540" upper="0.78540" velocity="5.92"/>
  </joint>
  <link name="Link_hip_r_roll">
    <inertial>
      <origin rpy="0 0 0" xyz="0.075725 -0.0010616 0.016591"/>
      <mass value="2.4334"/>
      <inertia ixx="0.0036961" ixy="-9E-07" ixz="0.0001644" iyy="0.0045067" iyz="6.3E-06" izz="0.0039063"/>
    </inertial>
    <visual>
      <origin rpy="0 0 0" xyz="0 0 0"/>
      <geometry>
        <mesh filename="package://azureloong_description/meshes/Link_hip_r_roll.STL"/>
      </geometry>
      <material name="">
        <color rgba="0.89804 0.91765 0.92941 1"/>
      </material>
    </visual>
    <collision>
      <origin rpy="0 0 0" xyz="0 0 0"/>
      <geometry>
        <mesh filename="package://azureloong_description/meshes/Link_hip_r_roll.STL"/>
      </geometry>
    </collision>
  </link>
  <joint name="J_hip_r_roll" type="revolute">
    <origin rpy="0 0 0" xyz="-0.0875 -0.12 -0.069"/>
    <parent link="Link_waist_yaw"/>
    <child link="Link_hip_r_roll"/>
    <axis xyz="1 0 0"/>
    <limit effort="320" lower="-0.17453" upper="0.43633" velocity="20.94"/>
  </joint>
  <link name="Link_hip_r_yaw">
    <inertial>
      <origin rpy="0 0 0" xyz="-3.0911E-08 -0.0071356 -0.10063"/>
      <mass value="3.4303"/>
      <inertia ixx="0.0077365" ixy="0" ixz="0" iyy="0.0080807" iyz="0.0001167" izz="0.006641"/>
    </inertial>
    <visual>
      <origin rpy="0 0 0" xyz="0 0 0"/>
      <geometry>
        <mesh filename="package://azureloong_description/meshes/Link_hip_r_yaw.STL"/>
      </geometry>
      <material name="">
        <color rgba="0.89804 0.91765 0.92941 1"/>
      </material>
    </visual>
    <collision>
      <origin rpy="0 0 0" xyz="0 0 0"/>
      <geometry>
        <mesh filename="package://azureloong_description/meshes/Link_hip_r_yaw.STL"/>
      </geometry>
    </collision>
  </link>
  <joint name="J_hip_r_yaw" type="revolute">
    <origin rpy="0 0 0" xyz="0.08225 -0.001 -0.01"/>
    <parent link="Link_hip_r_roll"/>
    <child link="Link_hip_r_yaw"/>
    <axis xyz="0 0 1"/>
    <limit effort="160" lower="-0.69813" upper="0.69813" velocity="19.63"/>
  </joint>
  <link name="Link_hip_r_pitch">
    <inertial>
      <origin rpy="0 0 0" xyz="0.0010856 -0.05497 -0.14535"/>
      <mass value="5.2378"/>
      <inertia ixx="0.043457" ixy="0.0002478" ixz="-0.0007626" iyy="0.037801" iyz="-0.0007431" izz="0.015183"/>
    </inertial>
    <visual>
      <origin rpy="0 0 0" xyz="0 0 0"/>
      <geometry>
        <mesh filename="package://azureloong_description/meshes/Link_hip_r_pitch.STL"/>
      </geometry>
      <material name="">
        <color rgba="0.69804 0.69804 0.69804 1"/>
      </material>
    </visual>
    <collision>
      <origin rpy="0 0 0" xyz="0 0 0"/>
      <geometry>
        <mesh filename="package://azureloong_description/meshes/Link_hip_r_pitch.STL"/>
      </geometry>
    </collision>
  </link>
  <joint name="J_hip_r_pitch" type="revolute">
    <origin rpy="0 0 0" xyz="0 0.03675 -0.1055"/>
    <parent link="Link_hip_r_yaw"/>
    <child link="Link_hip_r_pitch"/>
    <axis xyz="0 -1 0"/>
    <limit effort="396" lower="-0.78540" upper="1.83260" velocity="19.16"/>
  </joint>
  <link name="Link_knee_r_pitch">
    <inertial>
      <origin rpy="0 0 0" xyz="-0.0096425 2.9338E-06 -0.13601"/>
      <mass value="2.9775"/>
      <inertia ixx="0.02386" ixy="6.76E-05" ixz="-0.0004656" iyy="0.024184" iyz="-0.0005481" izz="0.0023083"/>
    </inertial>
    <visual>
      <origin rpy="0 0 0" xyz="0 0 0"/>
      <geometry>
        <mesh filename="package://azureloong_description/meshes/Link_knee_r_pitch.STL"/>
      </geometry>
      <material name="">
        <color rgba="0.66667 0.69804 0.76863 1"/>
      </material>
    </visual>
    <collision>
      <origin rpy="0 0 0" xyz="0 0 0"/>
      <geometry>
        <mesh filename="package://azureloong_description/meshes/Link_knee_r_pitch.STL"/>
      </geometry>
    </collision>
  </link>
  <joint name="J_knee_r_pitch" type="revolute">
    <origin rpy="0 0 0" xyz="0 -0.01125 -0.4"/>
    <parent link="Link_hip_r_pitch"/>
    <child link="Link_knee_r_pitch"/>
    <axis xyz="0 -1 0"/>
    <limit effort="396" lower="-2.35619" upper="0.08727" velocity="19.16"/>
  </joint>
  <link name="Link_ankle_r_pitch">
    <inertial>
      <origin rpy="0 0 0" xyz="-6.1835E-12 -1.2655E-07 -2.4682E-08"/>
      <mass value="0.10145"/>
      <inertia ixx="2.7175E-05" ixy="1.0023E-14" ixz="-8.1752E-13" iyy="6.1118E-06" iyz="2.6285E-11" izz="2.6565E-05"/>
    </inertial>
    <visual>
      <origin rpy="0 0 0" xyz="0 0 0"/>
      <geometry>
        <mesh filename="package://azureloong_description/meshes/Link_ankle_r_pitch.STL"/>
      </geometry>
      <material name="">
        <color rgba="0.52941 0.54902 0.54902 1"/>
      </material>
    </visual>
    <collision>
      <origin rpy="0 0 0" xyz="0 0 0"/>
      <geometry>
        <mesh filename="package://azureloong_description/meshes/Link_ankle_r_pitch.STL"/>
      </geometry>
    </collision>
  </link>
  <joint name="J_ankle_r_pitch" type="revolute">
    <origin rpy="0 0 0" xyz="0 0 -0.387"/>
    <parent link="Link_knee_r_pitch"/>
    <child link="Link_ankle_r_pitch"/>
    <axis xyz="0 -1 0"/>
    <limit effort="58.5" lower="-0.43633" upper="0.61087" velocity="48.8"/>
  </joint>
  <link name="Link_ankle_r_roll">
    <inertial>
      <origin rpy="0 0 0" xyz="0.041078 -8.9152E-08 -0.043909"/>
      <mass value="0.75229"/>
      <inertia ixx="0.0004393" ixy="0" ixz="-0.000269" iyy="0.0036465" iyz="0" izz="0.0036369"/>
    </inertial>
    <visual>
      <origin rpy="0 0 0" xyz="0 0 0"/>
      <geometry>
        <mesh filename="package://azureloong_description/meshes/Link_ankle_r_roll.STL"/>
      </geometry>
      <material name="">
        <color rgba="0.89804 0.91765 0.92941 1"/>
      </material>
    </visual>
    <!--collision>
      <origin rpy="0 0 0" xyz="0 0 0"/>
      <geometry>
        <mesh filename="package://azureloong_description/meshes/Link_ankle_r_roll.STL"/>
      </geometry>
    </collision-->
    <collision name="Link_ankle_r_roll_collision">
      <origin rpy="0 0 0" xyz="0.05 0 -0.05"/>
      <geometry>
        <box size="0.25 0.02 0.04"/>
      </geometry>
    </collision>
  </link>
  <joint name="J_ankle_r_roll" type="revolute">
    <origin rpy="0 0 0" xyz="0 0 0"/>
    <parent link="Link_ankle_r_pitch"/>
    <child link="Link_ankle_r_roll"/>
    <axis xyz="1 0 0"/>
    <limit effort="58.5" lower="-0.43633" upper="0.43633" velocity="48.8"/>
  </joint>
  <link name="Link_hip_l_roll">
    <inertial>
      <origin rpy="0 0 0" xyz="0.075725 -0.00093843 0.016591"/>
      <mass value="2.4334"/>
      <inertia ixx="0.0034464" ixy="9E-07" ixz="0.0001904" iyy="0.0042569" iyz="-6.6E-06" izz="0.0039063"/>
    </inertial>
    <visual>
      <origin rpy="0 0 0" xyz="0 0 0"/>
      <geometry>
        <mesh filename="package://azureloong_description/meshes/Link_hip_l_roll.STL"/>
      </geometry>
      <material name="">
        <color rgba="0.89804 0.91765 0.92941 1"/>
      </material>
    </visual>
    <collision>
      <origin rpy="0 0 0" xyz="0 0 0"/>
      <geometry>
        <mesh filename="package://azureloong_description/meshes/Link_hip_l_roll.STL"/>
      </geometry>
    </collision>
  </link>
  <joint name="J_hip_l_roll" type="revolute">
    <origin rpy="0 0 0" xyz="-0.0875 0.12 -0.069"/>
    <parent link="Link_waist_yaw"/>
    <child link="Link_hip_l_roll"/>
    <axis xyz="1 0 0"/>
    <limit effort="320" lower="-0.17453" upper="0.43633" velocity="20.94"/>
  </joint>
  <link name="Link_hip_l_yaw">
    <inertial>
      <origin rpy="0 0 0" xyz="-3.1716E-08 0.0071358 -0.10063"/>
      <mass value="3.4304"/>
      <inertia ixx="0.0077365" ixy="0" ixz="0" iyy="0.0080807" iyz="-0.0001167" izz="0.0066409"/>
    </inertial>
    <visual>
      <origin rpy="0 0 0" xyz="0 0 0"/>
      <geometry>
        <mesh filename="package://azureloong_description/meshes/Link_hip_l_yaw.STL"/>
      </geometry>
      <material name="">
        <color rgba="0.89804 0.91765 0.92941 1"/>
      </material>
    </visual>
    <collision>
      <origin rpy="0 0 0" xyz="0 0 0"/>
      <geometry>
        <mesh filename="package://azureloong_description/meshes/Link_hip_l_yaw.STL"/>
      </geometry>
    </collision>
  </link>
  <joint name="J_hip_l_yaw" type="revolute">
    <origin rpy="0 0 0" xyz="0.08225 -0.001 -0.01"/>
    <parent link="Link_hip_l_roll"/>
    <child link="Link_hip_l_yaw"/>
    <axis xyz="0 0 1"/>
    <limit effort="160" lower="-0.69813" upper="0.69813" velocity="19.63"/>
  </joint>
  <link name="Link_hip_l_pitch">
    <inertial>
      <origin rpy="0 0 0" xyz="0.0010856 0.05497 -0.14535"/>
      <mass value="5.2378"/>
      <inertia ixx="0.043457" ixy="-0.0002479" ixz="-0.0007626" iyy="0.037801" iyz="0.0007431" izz="0.015183"/>
    </inertial>
    <visual>
      <origin rpy="0 0 0" xyz="0 0 0"/>
      <geometry>
        <mesh filename="package://azureloong_description/meshes/Link_hip_l_pitch.STL"/>
      </geometry>
      <material name="">
        <color rgba="0.69804 0.69804 0.69804 1"/>
      </material>
    </visual>
    <collision>
      <origin rpy="0 0 0" xyz="0 0 0"/>
      <geometry>
        <mesh filename="package://azureloong_description/meshes/Link_hip_l_pitch.STL"/>
      </geometry>
    </collision>
  </link>
  <joint name="J_hip_l_pitch" type="revolute">
    <origin rpy="0 0 0" xyz="0 -0.03675 -0.1055"/>
    <parent link="Link_hip_l_yaw"/>
    <child link="Link_hip_l_pitch"/>
    <axis xyz="0 -1 0"/>
    <limit effort="396" lower="-0.78540" upper="1.83260" velocity="19.16"/>
  </joint>
  <link name="Link_knee_l_pitch">
    <inertial>
      <origin rpy="0 0 0" xyz="-0.0096425 -2.8684E-06 -0.13601"/>
      <mass value="2.9775"/>
      <inertia ixx="0.023859" ixy="-6.76E-05" ixz="-0.0004656" iyy="0.024183" iyz="0.000548" izz="0.0023083"/>
    </inertial>
    <visual>
      <origin rpy="0 0 0" xyz="0 0 0"/>
      <geometry>
        <mesh filename="package://azureloong_description/meshes/Link_knee_l_pitch.STL"/>
      </geometry>
      <material name="">
        <color rgba="0.66667 0.69804 0.76863 1"/>
      </material>
    </visual>
    <collision>
      <origin rpy="0 0 0" xyz="0 0 0"/>
      <geometry>
        <mesh filename="package://azureloong_description/meshes/Link_knee_l_pitch.STL"/>
      </geometry>
    </collision>
  </link>
  <joint name="J_knee_l_pitch" type="revolute">
    <origin rpy="0 0 0" xyz="0 0.01125 -0.4"/>
    <parent link="Link_hip_l_pitch"/>
    <child link="Link_knee_l_pitch"/>
    <axis xyz="0 -1 0"/>
    <limit effort="396" lower="-2.35619" upper="0.08727" velocity="19.16"/>
  </joint>
  <link name="Link_ankle_l_pitch">
    <inertial>
      <origin rpy="0 0 0" xyz="-6.1835E-12 1.2655E-07 6.7022E-08"/>
      <mass value="0.10145"/>
      <inertia ixx="2.7175E-05" ixy="-1.0023E-14" ixz="-8.1752E-13" iyy="6.1118E-06" iyz="-2.6285E-11" izz="2.6565E-05"/>
    </inertial>
    <visual>
      <origin rpy="0 0 0" xyz="0 0 0"/>
      <geometry>
        <mesh filename="package://azureloong_description/meshes/Link_ankle_l_pitch.STL"/>
      </geometry>
      <material name="">
        <color rgba="0.52941 0.54902 0.54902 1"/>
      </material>
    </visual>
    <collision>
      <origin rpy="0 0 0" xyz="0 0 0"/>
      <geometry>
        <mesh filename="package://azureloong_description/meshes/Link_ankle_l_pitch.STL"/>
      </geometry>
    </collision>
  </link>
  <joint name="J_ankle_l_pitch" type="revolute">
    <origin rpy="0 0 0" xyz="0 0 -0.387"/>
    <parent link="Link_knee_l_pitch"/>
    <child link="Link_ankle_l_pitch"/>
    <axis xyz="0 -1 0"/>
    <limit effort="58.5" lower="-0.43644" upper="0.61087" velocity="48.8"/>
  </joint>
  <link name="Link_ankle_l_roll">
    <inertial>
      <origin rpy="0 0 0" xyz="0.041077 -2.9318E-08 -0.043909"/>
      <mass value="0.7522882"/>
      <inertia ixx="0.0004393" ixy="0" ixz="-0.000269" iyy="0.0036465" iyz="0" izz="0.0036369"/>
    </inertial>
    <visual>
      <origin rpy="0 0 0" xyz="0 0 0"/>
      <geometry>
        <mesh filename="package://azureloong_description/meshes/Link_ankle_l_roll.STL"/>
      </geometry>
      <material name="">
        <color rgba="0.89804 0.91765 0.92941 1"/>
      </material>
    </visual>
    <!--collision>
      <origin rpy="0 0 0" xyz="0 0 0"/>
      <geometry>
        <mesh filename="package://azureloong_description/meshes/Link_ankle_l_roll.STL"/>
      </geometry>
    </collision-->
    <collision name="Link_ankle_l_roll_collision">
      <origin rpy="0 0 0" xyz="0.05 0 -0.05"/>
      <geometry>
        <box size="0.25 0.02 0.04"/>
      </geometry>
    </collision>
  </link>
  <joint name="J_ankle_l_roll" type="revolute">
    <origin rpy="0 0 0" xyz="0 0 0"/>
    <parent link="Link_ankle_l_pitch"/>
    <child link="Link_ankle_l_roll"/>
    <axis xyz="1 0 0"/>
    <limit effort="58.5" lower="-0.43633" upper="0.43633" velocity="48.8"/>
  </joint>
  <transmission name="J_head_yaw_tran">
    <type>transmission_interface/SimpleTransmission</type>
    <joint name="J_head_yaw">
      <hardwareInterface>hardware_interface/EffortJointInterface</hardwareInterface>
    </joint>
    <actuator name="J_head_yaw_motor">
      <hardwareInterface>hardware_interface/EffortJointInterface</hardwareInterface>
      <mechanicalReduction>1</mechanicalReduction>
    </actuator>
  </transmission>
  <transmission name="J_head_pitch_tran">
    <type>transmission_interface/SimpleTransmission</type>
    <joint name="J_head_pitch">
      <hardwareInterface>hardware_interface/EffortJointInterface</hardwareInterface>
    </joint>
    <actuator name="J_head_pitch_motor">
      <hardwareInterface>hardware_interface/EffortJointInterface</hardwareInterface>
      <mechanicalReduction>1</mechanicalReduction>
    </actuator>
  </transmission>
  <transmission name="J_arm_r_01_tran">
    <type>transmission_interface/SimpleTransmission</type>
    <joint name="J_arm_r_01">
      <hardwareInterface>hardware_interface/EffortJointInterface</hardwareInterface>
    </joint>
    <actuator name="J_arm_r_01_motor">
      <hardwareInterface>hardware_interface/EffortJointInterface</hardwareInterface>
      <mechanicalReduction>1</mechanicalReduction>
    </actuator>
  </transmission>
  <transmission name="J_arm_r_02_tran">
    <type>transmission_interface/SimpleTransmission</type>
    <joint name="J_arm_r_02">
      <hardwareInterface>hardware_interface/EffortJointInterface</hardwareInterface>
    </joint>
    <actuator name="J_arm_r_02_motor">
      <hardwareInterface>hardware_interface/EffortJointInterface</hardwareInterface>
      <mechanicalReduction>1</mechanicalReduction>
    </actuator>
  </transmission>
  <transmission name="J_arm_r_03_tran">
    <type>transmission_interface/SimpleTransmission</type>
    <joint name="J_arm_r_03">
      <hardwareInterface>hardware_interface/EffortJointInterface</hardwareInterface>
    </joint>
    <actuator name="J_arm_r_03_motor">
      <hardwareInterface>hardware_interface/EffortJointInterface</hardwareInterface>
      <mechanicalReduction>1</mechanicalReduction>
    </actuator>
  </transmission>
  <transmission name="J_arm_r_04_tran">
    <type>transmission_interface/SimpleTransmission</type>
    <joint name="J_arm_r_04">
      <hardwareInterface>hardware_interface/EffortJointInterface</hardwareInterface>
    </joint>
    <actuator name="J_arm_r_04_motor">
      <hardwareInterface>hardware_interface/EffortJointInterface</hardwareInterface>
      <mechanicalReduction>1</mechanicalReduction>
    </actuator>
  </transmission>
  <transmission name="J_arm_r_05_tran">
    <type>transmission_interface/SimpleTransmission</type>
    <joint name="J_arm_r_05">
      <hardwareInterface>hardware_interface/EffortJointInterface</hardwareInterface>
    </joint>
    <actuator name="J_arm_r_05_motor">
      <hardwareInterface>hardware_interface/EffortJointInterface</hardwareInterface>
      <mechanicalReduction>1</mechanicalReduction>
    </actuator>
  </transmission>
  <transmission name="J_arm_r_06_tran">
    <type>transmission_interface/SimpleTransmission</type>
    <joint name="J_arm_r_06">
      <hardwareInterface>hardware_interface/EffortJointInterface</hardwareInterface>
    </joint>
    <actuator name="J_arm_r_06_motor">
      <hardwareInterface>hardware_interface/EffortJointInterface</hardwareInterface>
      <mechanicalReduction>1</mechanicalReduction>
    </actuator>
  </transmission>
  <transmission name="J_arm_r_07_tran">
    <type>transmission_interface/SimpleTransmission</type>
    <joint name="J_arm_r_07">
      <hardwareInterface>hardware_interface/EffortJointInterface</hardwareInterface>
    </joint>
    <actuator name="J_arm_r_07_motor">
      <hardwareInterface>hardware_interface/EffortJointInterface</hardwareInterface>
      <mechanicalReduction>1</mechanicalReduction>
    </actuator>
  </transmission>
  <transmission name="J_arm_l_01_tran">
    <type>transmission_interface/SimpleTransmission</type>
    <joint name="J_arm_l_01">
      <hardwareInterface>hardware_interface/EffortJointInterface</hardwareInterface>
    </joint>
    <actuator name="J_arm_l_01_motor">
      <hardwareInterface>hardware_interface/EffortJointInterface</hardwareInterface>
      <mechanicalReduction>1</mechanicalReduction>
    </actuator>
  </transmission>
  <transmission name="J_arm_l_02_tran">
    <type>transmission_interface/SimpleTransmission</type>
    <joint name="J_arm_l_02">
      <hardwareInterface>hardware_interface/EffortJointInterface</hardwareInterface>
    </joint>
    <actuator name="J_arm_l_02_motor">
      <hardwareInterface>hardware_interface/EffortJointInterface</hardwareInterface>
      <mechanicalReduction>1</mechanicalReduction>
    </actuator>
  </transmission>
  <transmission name="J_arm_l_03_tran">
    <type>transmission_interface/SimpleTransmission</type>
    <joint name="J_arm_l_03">
      <hardwareInterface>hardware_interface/EffortJointInterface</hardwareInterface>
    </joint>
    <actuator name="J_arm_l_03_motor">
      <hardwareInterface>hardware_interface/EffortJointInterface</hardwareInterface>
      <mechanicalReduction>1</mechanicalReduction>
    </actuator>
  </transmission>
  <transmission name="J_arm_l_04_tran">
    <type>transmission_interface/SimpleTransmission</type>
    <joint name="J_arm_l_04">
      <hardwareInterface>hardware_interface/EffortJointInterface</hardwareInterface>
    </joint>
    <actuator name="J_arm_l_04_motor">
      <hardwareInterface>hardware_interface/EffortJointInterface</hardwareInterface>
      <mechanicalReduction>1</mechanicalReduction>
    </actuator>
  </transmission>
  <transmission name="J_arm_l_05_tran">
    <type>transmission_interface/SimpleTransmission</type>
    <joint name="J_arm_l_05">
      <hardwareInterface>hardware_interface/EffortJointInterface</hardwareInterface>
    </joint>
    <actuator name="J_arm_l_05_motor">
      <hardwareInterface>hardware_interface/EffortJointInterface</hardwareInterface>
      <mechanicalReduction>1</mechanicalReduction>
    </actuator>
  </transmission>
  <transmission name="J_arm_l_06_tran">
    <type>transmission_interface/SimpleTransmission</type>
    <joint name="J_arm_l_06">
      <hardwareInterface>hardware_interface/EffortJointInterface</hardwareInterface>
    </joint>
    <actuator name="J_arm_l_06_motor">
      <hardwareInterface>hardware_interface/EffortJointInterface</hardwareInterface>
      <mechanicalReduction>1</mechanicalReduction>
    </actuator>
  </transmission>
  <transmission name="J_arm_l_07_tran">
    <type>transmission_interface/SimpleTransmission</type>
    <joint name="J_arm_l_07">
      <hardwareInterface>hardware_interface/EffortJointInterface</hardwareInterface>
    </joint>
    <actuator name="J_arm_l_07_motor">
      <hardwareInterface>hardware_interface/EffortJointInterface</hardwareInterface>
      <mechanicalReduction>1</mechanicalReduction>
    </actuator>
  </transmission>
  <transmission name="J_waist_pitch_tran">
    <type>transmission_interface/SimpleTransmission</type>
    <joint name="J_waist_pitch">
      <hardwareInterface>hardware_interface/EffortJointInterface</hardwareInterface>
    </joint>
    <actuator name="J_waist_pitch_motor">
      <hardwareInterface>hardware_interface/EffortJointInterface</hardwareInterface>
      <mechanicalReduction>1</mechanicalReduction>
    </actuator>
  </transmission>
  <transmission name="J_waist_roll_tran">
    <type>transmission_interface/SimpleTransmission</type>
    <joint name="J_waist_roll">
      <hardwareInterface>hardware_interface/EffortJointInterface</hardwareInterface>
    </joint>
    <actuator name="J_waist_roll_motor">
      <hardwareInterface>hardware_interface/EffortJointInterface</hardwareInterface>
      <mechanicalReduction>1</mechanicalReduction>
    </actuator>
  </transmission>
  <transmission name="J_waist_yaw_tran">
    <type>transmission_interface/SimpleTransmission</type>
    <joint name="J_waist_yaw">
      <hardwareInterface>hardware_interface/EffortJointInterface</hardwareInterface>
    </joint>
    <actuator name="J_waist_yaw_motor">
      <hardwareInterface>hardware_interface/EffortJointInterface</hardwareInterface>
      <mechanicalReduction>1</mechanicalReduction>
    </actuator>
  </transmission>
  <transmission name="J_hip_r_roll_tran">
    <type>transmission_interface/SimpleTransmission</type>
    <joint name="J_hip_r_roll">
      <hardwareInterface>hardware_interface/EffortJointInterface</hardwareInterface>
    </joint>
    <actuator name="J_hip_r_roll_motor">
      <hardwareInterface>hardware_interface/EffortJointInterface</hardwareInterface>
      <mechanicalReduction>1</mechanicalReduction>
    </actuator>
  </transmission>
  <transmission name="J_hip_r_yaw_tran">
    <type>transmission_interface/SimpleTransmission</type>
    <joint name="J_hip_r_yaw">
      <hardwareInterface>hardware_interface/EffortJointInterface</hardwareInterface>
    </joint>
    <actuator name="J_hip_r_yaw_motor">
      <hardwareInterface>hardware_interface/EffortJointInterface</hardwareInterface>
      <mechanicalReduction>1</mechanicalReduction>
    </actuator>
  </transmission>
  <transmission name="J_hip_r_pitch_tran">
    <type>transmission_interface/SimpleTransmission</type>
    <joint name="J_hip_r_pitch">
      <hardwareInterface>hardware_interface/EffortJointInterface</hardwareInterface>
    </joint>
    <actuator name="J_hip_r_pitch_motor">
      <hardwareInterface>hardware_interface/EffortJointInterface</hardwareInterface>
      <mechanicalReduction>1</mechanicalReduction>
    </actuator>
  </transmission>
  <transmission name="J_knee_r_pitch_tran">
    <type>transmission_interface/SimpleTransmission</type>
    <joint name="J_knee_r_pitch">
      <hardwareInterface>hardware_interface/EffortJointInterface</hardwareInterface>
    </joint>
    <actuator name="J_knee_r_pitch_motor">
      <hardwareInterface>hardware_interface/EffortJointInterface</hardwareInterface>
      <mechanicalReduction>1</mechanicalReduction>
    </actuator>
  </transmission>
  <transmission name="J_ankle_r_pitch_tran">
    <type>transmission_interface/SimpleTransmission</type>
    <joint name="J_ankle_r_pitch">
      <hardwareInterface>hardware_interface/EffortJointInterface</hardwareInterface>
    </joint>
    <actuator name="J_ankle_r_pitch_motor">
      <hardwareInterface>hardware_interface/EffortJointInterface</hardwareInterface>
      <mechanicalReduction>1</mechanicalReduction>
    </actuator>
  </transmission>
  <transmission name="J_ankle_r_roll_tran">
    <type>transmission_interface/SimpleTransmission</type>
    <joint name="J_ankle_r_roll">
      <hardwareInterface>hardware_interface/EffortJointInterface</hardwareInterface>
    </joint>
    <actuator name="J_ankle_r_roll_motor">
      <hardwareInterface>hardware_interface/EffortJointInterface</hardwareInterface>
      <mechanicalReduction>1</mechanicalReduction>
    </actuator>
  </transmission>
  <transmission name="J_hip_l_roll_tran">
    <type>transmission_interface/SimpleTransmission</type>
    <joint name="J_hip_l_roll">
      <hardwareInterface>hardware_interface/EffortJointInterface</hardwareInterface>
    </joint>
    <actuator name="J_hip_l_roll_motor">
      <hardwareInterface>hardware_interface/EffortJointInterface</hardwareInterface>
      <mechanicalReduction>1</mechanicalReduction>
    </actuator>
  </transmission>
  <transmission name="J_hip_l_yaw_tran">
    <type>transmission_interface/SimpleTransmission</type>
    <joint name="J_hip_l_yaw">
      <hardwareInterface>hardware_interface/EffortJointInterface</hardwareInterface>
    </joint>
    <actuator name="J_hip_l_yaw_motor">
      <hardwareInterface>hardware_interface/EffortJointInterface</hardwareInterface>
      <mechanicalReduction>1</mechanicalReduction>
    </actuator>
  </transmission>
  <transmission name="J_hip_l_pitch_tran">
    <type>transmission_interface/SimpleTransmission</type>
    <joint name="J_hip_l_pitch">
      <hardwareInterface>hardware_interface/EffortJointInterface</hardwareInterface>
    </joint>
    <actuator name="J_hip_l_pitch_motor">
      <hardwareInterface>hardware_interface/EffortJointInterface</hardwareInterface>
      <mechanicalReduction>1</mechanicalReduction>
    </actuator>
  </transmission>
  <transmission name="J_knee_l_pitch_tran">
    <type>transmission_interface/SimpleTransmission</type>
    <joint name="J_knee_l_pitch">
      <hardwareInterface>hardware_interface/EffortJointInterface</hardwareInterface>
    </joint>
    <actuator name="J_knee_l_pitch_motor">
      <hardwareInterface>hardware_interface/EffortJointInterface</hardwareInterface>
      <mechanicalReduction>1</mechanicalReduction>
    </actuator>
  </transmission>
  <transmission name="J_ankle_l_pitch_tran">
    <type>transmission_interface/SimpleTransmission</type>
    <joint name="J_ankle_l_pitch">
      <hardwareInterface>hardware_interface/EffortJointInterface</hardwareInterface>
    </joint>
    <actuator name="J_ankle_l_pitch_motor">
      <hardwareInterface>hardware_interface/EffortJointInterface</hardwareInterface>
      <mechanicalReduction>1</mechanicalReduction>
    </actuator>
  </transmission>
  <transmission name="J_ankle_l_roll_tran">
    <type>transmission_interface/SimpleTransmission</type>
    <joint name="J_ankle_l_roll">
      <hardwareInterface>hardware_interface/EffortJointInterface</hardwareInterface>
    </joint>
    <actuator name="J_ankle_l_roll_motor">
      <hardwareInterface>hardware_interface/EffortJointInterface</hardwareInterface>
      <mechanicalReduction>1</mechanicalReduction>
    </actuator>
  </transmission>
  <gazebo>
    <plugin filename="libgazebo_ros_control.so" name="gazebo_ros_control">
      <robotNamespace>/</robotNamespace>
      <robotSimType>gazebo_ros_control/DefaultRobotHWSim</robotSimType>
    </plugin>
  </gazebo>
  <joint name="imu_joint" type="fixed">
    <parent link="base"/>
    <child link="imu_link"/>
    <origin rpy="0 0 0" xyz="0 0 0"/>
  </joint>
  <link name="imu_link"/>
  <gazebo reference="imu_link">
    <gravity>true</gravity>
    <sensor name="imu_sensor" type="imu">
      <always_on>true</always_on>
      <update_rate>1000</update_rate>
      <visualize>true</visualize>
      <topic>__default_topic__</topic>
      <plugin filename="libgazebo_ros_imu_sensor.so" name="imu_plugin">
        <topicName>trunk_imu</topicName>
        <bodyName>imu_link</bodyName>
        <updateRateHZ>1000.0</updateRateHZ>
        <gaussianNoise>0.00</gaussianNoise>
        <xyzOffset>0 0 0</xyzOffset>
        <rpyOffset>0 0 0</rpyOffset>
        <frameName>imu_link</frameName>
      </plugin>
      <pose>0 0 0 0 0 0</pose>
    </sensor>
  </gazebo>
</robot>

